<sdf version='1.7'>
  <world name='default'>
    <light name='sun' type='directional'>
      <cast_shadows>1</cast_shadows>
      <pose>0 0 10 0 -0 0</pose>
      <diffuse>0.8 0.8 0.8 1</diffuse>
      <specular>0.2 0.2 0.2 1</specular>
      <attenuation>
        <range>1000</range>
        <constant>0.9</constant>
        <linear>0.01</linear>
        <quadratic>0.001</quadratic>
      </attenuation>
      <direction>-0.5 0.1 -0.9</direction>
      <spot>
        <inner_angle>0</inner_angle>
        <outer_angle>0</outer_angle>
        <falloff>0</falloff>
      </spot>
    </light>
    <model name='ground_plane'>
      <static>1</static>
      <link name='link'>
        <collision name='collision'>
          <geometry>
            <plane>
              <normal>0 0 1</normal>
              <size>100 100</size>
            </plane>
          </geometry>
          <surface>
            <friction>
              <ode>
                <mu>100</mu>
                <mu2>50</mu2>
              </ode>
              <torsional>
                <ode/>
              </torsional>
            </friction>
            <contact>
              <ode/>
            </contact>
            <bounce/>
          </surface>
          <max_contacts>10</max_contacts>
        </collision>
        <visual name='visual'>
          <cast_shadows>0</cast_shadows>
          <geometry>
            <plane>
              <normal>0 0 1</normal>
              <size>100 100</size>
            </plane>
          </geometry>
          <material>
            <script>
              <uri>file://media/materials/scripts/gazebo.material</uri>
              <name>Gazebo/Grey</name>
            </script>
          </material>
        </visual>
        <self_collide>0</self_collide>
        <enable_wind>0</enable_wind>
        <kinematic>0</kinematic>
      </link>
    </model>
    <gravity>0 0 -9.8</gravity>
    <magnetic_field>6e-06 2.3e-05 -4.2e-05</magnetic_field>
    <atmosphere type='adiabatic'/>
    <physics type='ode'>
      <max_step_size>0.001</max_step_size>
      <real_time_factor>1</real_time_factor>
      <real_time_update_rate>1000</real_time_update_rate>
    </physics>
    <scene>
      <ambient>0.4 0.4 0.4 1</ambient>
      <background>0.7 0.7 0.7 1</background>
      <shadows>1</shadows>
    </scene>
    <audio>
      <device>default</device>
    </audio>
    <wind/>
    <spherical_coordinates>
      <surface_model>EARTH_WGS84</surface_model>
      <latitude_deg>0</latitude_deg>
      <longitude_deg>0</longitude_deg>
      <elevation>0</elevation>
      <heading_deg>0</heading_deg>
    </spherical_coordinates>
    <model name='simple'>
      <pose>0.011754 -0.028761 0 0 -0 0</pose>
      <link name='Wall_1'>
        <collision name='Wall_1_Collision'>
          <geometry>
            <box>
              <size>12.75 0.15 2.5</size>
            </box>
          </geometry>
          <pose>0 0 1.25 0 -0 0</pose>
          <max_contacts>10</max_contacts>
          <surface>
            <contact>
              <ode/>
            </contact>
            <bounce/>
            <friction>
              <torsional>
                <ode/>
              </torsional>
              <ode/>
            </friction>
          </surface>
        </collision>
        <visual name='Wall_1_Visual'>
          <pose>0 0 1.25 0 -0 0</pose>
          <geometry>
            <box>
              <size>12.75 0.15 2.5</size>
            </box>
          </geometry>
          <material>
            <script>
              <uri>file://media/materials/scripts/gazebo.material</uri>
              <name>Gazebo/Bricks</name>
            </script>
            <ambient>1 1 1 1</ambient>
          </material>
          <meta>
            <layer>0</layer>
          </meta>
        </visual>
        <pose>0.375 5.55 0 0 -0 0</pose>
        <self_collide>0</self_collide>
        <enable_wind>0</enable_wind>
        <kinematic>0</kinematic>
      </link>
      <link name='Wall_10'>
        <collision name='Wall_10_Collision'>
          <geometry>
            <box>
              <size>6 0.15 2.5</size>
            </box>
          </geometry>
          <pose>0 0 1.25 0 -0 0</pose>
          <max_contacts>10</max_contacts>
          <surface>
            <contact>
              <ode/>
            </contact>
            <bounce/>
            <friction>
              <torsional>
                <ode/>
              </torsional>
              <ode/>
            </friction>
          </surface>
        </collision>
        <visual name='Wall_10_Visual'>
          <pose>0 0 1.25 0 -0 0</pose>
          <geometry>
            <box>
              <size>6 0.15 2.5</size>
            </box>
          </geometry>
          <material>
            <script>
              <uri>file://media/materials/scripts/gazebo.material</uri>
              <name>Gazebo/Bricks</name>
            </script>
            <ambient>1 1 1 1</ambient>
          </material>
          <meta>
            <layer>0</layer>
          </meta>
        </visual>
        <pose>3.67364 -1.41539 0 0 -0 3.14159</pose>
        <self_collide>0</self_collide>
        <enable_wind>0</enable_wind>
        <kinematic>0</kinematic>
      </link>
      <link name='Wall_13'>
        <collision name='Wall_13_Collision'>
          <geometry>
            <box>
              <size>4.25 0.15 2.5</size>
            </box>
          </geometry>
          <pose>0 0 1.25 0 -0 0</pose>
          <max_contacts>10</max_contacts>
          <surface>
            <contact>
              <ode/>
            </contact>
            <bounce/>
            <friction>
              <torsional>
                <ode/>
              </torsional>
              <ode/>
            </friction>
          </surface>
        </collision>
        <visual name='Wall_13_Visual'>
          <pose>0 0 1.25 0 -0 0</pose>
          <geometry>
            <box>
              <size>4.25 0.15 2.5</size>
            </box>
          </geometry>
          <material>
            <script>
              <uri>file://media/materials/scripts/gazebo.material</uri>
              <name>Gazebo/Bricks</name>
            </script>
            <ambient>1 1 1 1</ambient>
          </material>
          <meta>
            <layer>0</layer>
          </meta>
        </visual>
        <pose>-2.75121 -3.4473 0 0 -0 1.5708</pose>
        <self_collide>0</self_collide>
        <enable_wind>0</enable_wind>
        <kinematic>0</kinematic>
      </link>
      <link name='Wall_2'>
        <collision name='Wall_2_Collision'>
          <geometry>
            <box>
              <size>11.25 0.15 2.5</size>
            </box>
          </geometry>
          <pose>0 0 1.25 0 -0 0</pose>
          <max_contacts>10</max_contacts>
          <surface>
            <contact>
              <ode/>
            </contact>
            <bounce/>
            <friction>
              <torsional>
                <ode/>
              </torsional>
              <ode/>
            </friction>
          </surface>
        </collision>
        <visual name='Wall_2_Visual'>
          <pose>0 0 1.25 0 -0 0</pose>
          <geometry>
            <box>
              <size>11.25 0.15 2.5</size>
            </box>
          </geometry>
          <material>
            <script>
              <uri>file://media/materials/scripts/gazebo.material</uri>
              <name>Gazebo/Bricks</name>
            </script>
            <ambient>1 1 1 1</ambient>
          </material>
          <meta>
            <layer>0</layer>
          </meta>
        </visual>
        <pose>6.675 0 0 0 -0 -1.5708</pose>
        <self_collide>0</self_collide>
        <enable_wind>0</enable_wind>
        <kinematic>0</kinematic>
      </link>
      <link name='Wall_3'>
        <collision name='Wall_3_Collision'>
          <geometry>
            <box>
              <size>13.5 0.15 2.5</size>
            </box>
          </geometry>
          <pose>0 0 1.25 0 -0 0</pose>
          <max_contacts>10</max_contacts>
          <surface>
            <contact>
              <ode/>
            </contact>
            <bounce/>
            <friction>
              <torsional>
                <ode/>
              </torsional>
              <ode/>
            </friction>
          </surface>
        </collision>
        <visual name='Wall_3_Visual'>
          <pose>0 0 1.25 0 -0 0</pose>
          <geometry>
            <box>
              <size>13.5 0.15 2.5</size>
            </box>
          </geometry>
          <material>
            <script>
              <uri>file://media/materials/scripts/gazebo.material</uri>
              <name>Gazebo/Bricks</name>
            </script>
            <ambient>1 1 1 1</ambient>
          </material>
          <meta>
            <layer>0</layer>
          </meta>
        </visual>
        <pose>0 -5.55 0 0 -0 3.14159</pose>
        <self_collide>0</self_collide>
        <enable_wind>0</enable_wind>
        <kinematic>0</kinematic>
      </link>
      <link name='Wall_4'>
        <collision name='Wall_4_Collision'>
          <geometry>
            <box>
              <size>11.25 0.15 2.5</size>
            </box>
          </geometry>
          <pose>0 0 1.25 0 -0 0</pose>
          <max_contacts>10</max_contacts>
          <surface>
            <contact>
              <ode/>
            </contact>
            <bounce/>
            <friction>
              <torsional>
                <ode/>
              </torsional>
              <ode/>
            </friction>
          </surface>
        </collision>
        <visual name='Wall_4_Visual'>
          <pose>0 0 1.25 0 -0 0</pose>
          <geometry>
            <box>
              <size>11.25 0.15 2.5</size>
            </box>
          </geometry>
          <material>
            <script>
              <uri>file://media/materials/scripts/gazebo.material</uri>
              <name>Gazebo/Bricks</name>
            </script>
            <ambient>1 1 1 1</ambient>
          </material>
          <meta>
            <layer>0</layer>
          </meta>
        </visual>
        <pose>-6.675 0 0 0 -0 1.5708</pose>
        <self_collide>0</self_collide>
        <enable_wind>0</enable_wind>
        <kinematic>0</kinematic>
      </link>
      <link name='Wall_5'>
        <collision name='Wall_5_Collision'>
          <geometry>
            <box>
              <size>13.5 0.15 2.5</size>
            </box>
          </geometry>
          <pose>0 0 1.25 0 -0 0</pose>
          <max_contacts>10</max_contacts>
          <surface>
            <contact>
              <ode/>
            </contact>
            <bounce/>
            <friction>
              <torsional>
                <ode/>
              </torsional>
              <ode/>
            </friction>
          </surface>
        </collision>
        <visual name='Wall_5_Visual'>
          <pose>0 0 1.25 0 -0 0</pose>
          <geometry>
            <box>
              <size>13.5 0.15 2.5</size>
            </box>
          </geometry>
          <material>
            <script>
              <uri>file://media/materials/scripts/gazebo.material</uri>
              <name>Gazebo/Bricks</name>
            </script>
            <ambient>1 1 1 1</ambient>
          </material>
          <meta>
            <layer>0</layer>
          </meta>
        </visual>
        <pose>0 5.55 0 0 -0 0</pose>
        <self_collide>0</self_collide>
        <enable_wind>0</enable_wind>
        <kinematic>0</kinematic>
      </link>
      <link name='Wall_7'>
        <collision name='Wall_7_Collision'>
          <geometry>
            <box>
              <size>3.5 0.15 2.5</size>
            </box>
          </geometry>
          <pose>0 0 1.25 0 -0 0</pose>
          <max_contacts>10</max_contacts>
          <surface>
            <contact>
              <ode/>
            </contact>
            <bounce/>
            <friction>
              <torsional>
                <ode/>
              </torsional>
              <ode/>
            </friction>
          </surface>
        </collision>
        <visual name='Wall_7_Visual'>
          <pose>0 0 1.25 0 -0 0</pose>
          <geometry>
            <box>
              <size>3.5 0.15 2.5</size>
            </box>
          </geometry>
          <material>
            <script>
              <uri>file://media/materials/scripts/gazebo.material</uri>
              <name>Gazebo/Bricks</name>
            </script>
            <ambient>1 1 1 1</ambient>
          </material>
          <meta>
            <layer>0</layer>
          </meta>
        </visual>
        <pose>-2.89963 3.875 0 0 -0 -1.5708</pose>
        <self_collide>0</self_collide>
        <enable_wind>0</enable_wind>
        <kinematic>0</kinematic>
      </link>
      <link name='Wall_8'>
        <collision name='Wall_8_Collision'>
          <geometry>
            <box>
              <size>5.25 0.15 2.5</size>
            </box>
          </geometry>
          <pose>0 0 1.25 0 -0 0</pose>
          <max_contacts>10</max_contacts>
          <surface>
            <contact>
              <ode/>
            </contact>
            <bounce/>
            <friction>
              <torsional>
                <ode/>
              </torsional>
              <ode/>
            </friction>
          </surface>
        </collision>
        <visual name='Wall_8_Visual'>
          <pose>0 0 1.25 0 -0 0</pose>
          <geometry>
            <box>
              <size>5.25 0.15 2.5</size>
            </box>
          </geometry>
          <material>
            <script>
              <uri>file://media/materials/scripts/gazebo.material</uri>
              <name>Gazebo/Bricks</name>
            </script>
            <ambient>1 1 1 1</ambient>
          </material>
          <meta>
            <layer>0</layer>
          </meta>
        </visual>
        <pose>-0.349626 2.2 0 0 -0 0</pose>
        <self_collide>0</self_collide>
        <enable_wind>0</enable_wind>
        <kinematic>0</kinematic>
      </link>
      <static>1</static>
    </model>
    <model name='cafe_table'>
      <static>1</static>
      <link name='link'>
        <collision name='surface'>
          <pose>0 0 0.755 0 -0 0</pose>
          <geometry>
            <box>
              <size>0.913 0.913 0.04</size>
            </box>
          </geometry>
          <max_contacts>10</max_contacts>
          <surface>
            <contact>
              <ode/>
            </contact>
            <bounce/>
            <friction>
              <torsional>
                <ode/>
              </torsional>
              <ode/>
            </friction>
          </surface>
        </collision>
        <collision name='column'>
          <pose>0 0 0.37 0 -0 0</pose>
          <geometry>
            <box>
              <size>0.042 0.042 0.74</size>
            </box>
          </geometry>
          <max_contacts>10</max_contacts>
          <surface>
            <contact>
              <ode/>
            </contact>
            <bounce/>
            <friction>
              <torsional>
                <ode/>
              </torsional>
              <ode/>
            </friction>
          </surface>
        </collision>
        <collision name='base'>
          <pose>0 0 0.02 0 -0 0</pose>
          <geometry>
            <box>
              <size>0.56 0.56 0.04</size>
            </box>
          </geometry>
          <max_contacts>10</max_contacts>
          <surface>
            <contact>
              <ode/>
            </contact>
            <bounce/>
            <friction>
              <torsional>
                <ode/>
              </torsional>
              <ode/>
            </friction>
          </surface>
        </collision>
        <visual name='visual'>
          <geometry>
            <mesh>
              <uri>model://cafe_table/meshes/cafe_table.dae</uri>
            </mesh>
          </geometry>
        </visual>
        <self_collide>0</self_collide>
        <enable_wind>0</enable_wind>
        <kinematic>0</kinematic>
      </link>
      <pose>-1.50845 1.52359 0 0 -0 0</pose>
    </model>
    <model name='cafe_table_0'>
      <static>1</static>
      <link name='link'>
        <collision name='surface'>
          <pose>0 0 0.755 0 -0 0</pose>
          <geometry>
            <box>
              <size>0.913 0.913 0.04</size>
            </box>
          </geometry>
          <max_contacts>10</max_contacts>
          <surface>
            <contact>
              <ode/>
            </contact>
            <bounce/>
            <friction>
              <torsional>
                <ode/>
              </torsional>
              <ode/>
            </friction>
          </surface>
        </collision>
        <collision name='column'>
          <pose>0 0 0.37 0 -0 0</pose>
          <geometry>
            <box>
              <size>0.042 0.042 0.74</size>
            </box>
          </geometry>
          <max_contacts>10</max_contacts>
          <surface>
            <contact>
              <ode/>
            </contact>
            <bounce/>
            <friction>
              <torsional>
                <ode/>
              </torsional>
              <ode/>
            </friction>
          </surface>
        </collision>
        <collision name='base'>
          <pose>0 0 0.02 0 -0 0</pose>
          <geometry>
            <box>
              <size>0.56 0.56 0.04</size>
            </box>
          </geometry>
          <max_contacts>10</max_contacts>
          <surface>
            <contact>
              <ode/>
            </contact>
            <bounce/>
            <friction>
              <torsional>
                <ode/>
              </torsional>
              <ode/>
            </friction>
          </surface>
        </collision>
        <visual name='visual'>
          <geometry>
            <mesh>
              <uri>model://cafe_table/meshes/cafe_table.dae</uri>
            </mesh>
          </geometry>
        </visual>
        <self_collide>0</self_collide>
        <enable_wind>0</enable_wind>
        <kinematic>0</kinematic>
      </link>
      <pose>1.05085 1.48026 0 0 -0 0</pose>
    </model>
    <model name='bookshelf'>
      <static>1</static>
      <link name='link'>
        <inertial>
          <mass>1</mass>
        </inertial>
        <collision name='back'>
          <pose>0 0.005 0.6 0 -0 0</pose>
          <geometry>
            <box>
              <size>0.9 0.01 1.2</size>
            </box>
          </geometry>
          <max_contacts>10</max_contacts>
          <surface>
            <contact>
              <ode/>
            </contact>
            <bounce/>
            <friction>
              <torsional>
                <ode/>
              </torsional>
              <ode/>
            </friction>
          </surface>
        </collision>
        <visual name='visual1'>
          <pose>0 0.005 0.6 0 -0 0</pose>
          <geometry>
            <box>
              <size>0.9 0.01 1.2</size>
            </box>
          </geometry>
          <material>
            <script>
              <uri>file://media/materials/scripts/gazebo.material</uri>
              <name>Gazebo/Wood</name>
            </script>
          </material>
        </visual>
        <collision name='left_side'>
          <pose>0.45 -0.195 0.6 0 -0 0</pose>
          <geometry>
            <box>
              <size>0.02 0.4 1.2</size>
            </box>
          </geometry>
          <max_contacts>10</max_contacts>
          <surface>
            <contact>
              <ode/>
            </contact>
            <bounce/>
            <friction>
              <torsional>
                <ode/>
              </torsional>
              <ode/>
            </friction>
          </surface>
        </collision>
        <visual name='visual2'>
          <pose>0.45 -0.195 0.6 0 -0 0</pose>
          <geometry>
            <box>
              <size>0.02 0.4 1.2</size>
            </box>
          </geometry>
          <material>
            <script>
              <uri>file://media/materials/scripts/gazebo.material</uri>
              <name>Gazebo/Wood</name>
            </script>
          </material>
        </visual>
        <collision name='right_side'>
          <pose>-0.45 -0.195 0.6 0 -0 0</pose>
          <geometry>
            <box>
              <size>0.02 0.4 1.2</size>
            </box>
          </geometry>
          <max_contacts>10</max_contacts>
          <surface>
            <contact>
              <ode/>
            </contact>
            <bounce/>
            <friction>
              <torsional>
                <ode/>
              </torsional>
              <ode/>
            </friction>
          </surface>
        </collision>
        <visual name='visual3'>
          <pose>-0.45 -0.195 0.6 0 -0 0</pose>
          <geometry>
            <box>
              <size>0.02 0.4 1.2</size>
            </box>
          </geometry>
          <material>
            <script>
              <uri>file://media/materials/scripts/gazebo.material</uri>
              <name>Gazebo/Wood</name>
            </script>
          </material>
        </visual>
        <collision name='bottom'>
          <pose>0 -0.195 0.03 0 -0 0</pose>
          <geometry>
            <box>
              <size>0.88 0.4 0.06</size>
            </box>
          </geometry>
          <max_contacts>10</max_contacts>
          <surface>
            <contact>
              <ode/>
            </contact>
            <bounce/>
            <friction>
              <torsional>
                <ode/>
              </torsional>
              <ode/>
            </friction>
          </surface>
        </collision>
        <visual name='visual4'>
          <pose>0 -0.195 0.03 0 -0 0</pose>
          <geometry>
            <box>
              <size>0.88 0.4 0.06</size>
            </box>
          </geometry>
          <material>
            <script>
              <uri>file://media/materials/scripts/gazebo.material</uri>
              <name>Gazebo/Wood</name>
            </script>
          </material>
        </visual>
        <collision name='top'>
          <pose>0 -0.195 1.19 0 -0 0</pose>
          <geometry>
            <box>
              <size>0.88 0.4 0.02</size>
            </box>
          </geometry>
          <max_contacts>10</max_contacts>
          <surface>
            <contact>
              <ode/>
            </contact>
            <bounce/>
            <friction>
              <torsional>
                <ode/>
              </torsional>
              <ode/>
            </friction>
          </surface>
        </collision>
        <visual name='visual5'>
          <pose>0 -0.195 1.19 0 -0 0</pose>
          <geometry>
            <box>
              <size>0.88 0.4 0.02</size>
            </box>
          </geometry>
          <material>
            <script>
              <uri>file://media/materials/scripts/gazebo.material</uri>
              <name>Gazebo/Wood</name>
            </script>
          </material>
        </visual>
        <collision name='low_shelf'>
          <pose>0 -0.195 0.43 0 -0 0</pose>
          <geometry>
            <box>
              <size>0.88 0.4 0.02</size>
            </box>
          </geometry>
          <max_contacts>10</max_contacts>
          <surface>
            <contact>
              <ode/>
            </contact>
            <bounce/>
            <friction>
              <torsional>
                <ode/>
              </torsional>
              <ode/>
            </friction>
          </surface>
        </collision>
        <visual name='visual6'>
          <pose>0 -0.195 0.43 0 -0 0</pose>
          <geometry>
            <box>
              <size>0.88 0.4 0.02</size>
            </box>
          </geometry>
          <material>
            <script>
              <uri>file://media/materials/scripts/gazebo.material</uri>
              <name>Gazebo/Wood</name>
            </script>
          </material>
        </visual>
        <collision name='high_shelf'>
          <pose>0 -0.195 0.8 0 -0 0</pose>
          <geometry>
            <box>
              <size>0.88 0.4 0.02</size>
            </box>
          </geometry>
          <max_contacts>10</max_contacts>
          <surface>
            <contact>
              <ode/>
            </contact>
            <bounce/>
            <friction>
              <torsional>
                <ode/>
              </torsional>
              <ode/>
            </friction>
          </surface>
        </collision>
        <visual name='visual7'>
          <pose>0 -0.195 0.8 0 -0 0</pose>
          <geometry>
            <box>
              <size>0.88 0.4 0.02</size>
            </box>
          </geometry>
          <material>
            <script>
              <uri>file://media/materials/scripts/gazebo.material</uri>
              <name>Gazebo/Wood</name>
            </script>
          </material>
        </visual>
        <self_collide>0</self_collide>
        <enable_wind>0</enable_wind>
        <kinematic>0</kinematic>
      </link>
      <pose>-1.79353 -1.79183 0 0 -0 0</pose>
    </model>
    <model name='cinder_block_wide'>
      <link name='link'>
        <inertial>
          <pose>0 0 0.071438 0 -0 0</pose>
          <mass>5</mass>
          <inertia>
            <ixx>0.0681466</ixx>
            <ixy>0</ixy>
            <iyy>0.0681466</iyy>
            <ixz>0</ixz>
            <iyz>0</iyz>
            <izz>0.124808</izz>
          </inertia>
        </inertial>
        <visual name='visual'>
          <geometry>
            <mesh>
              <uri>model://cinder_block_wide/meshes/cinder_block_wide.dae</uri>
            </mesh>
          </geometry>
        </visual>
        <collision name='top'>
          <pose>0 0 0.130175 0 -0 0</pose>
          <geometry>
            <box>
              <size>0.387354 0.387354 0.0254</size>
            </box>
          </geometry>
          <surface>
            <contact>
              <ode>
                <max_vel>0.1</max_vel>
                <min_depth>0.001</min_depth>
              </ode>
            </contact>
            <friction>
              <ode>
                <mu>1</mu>
                <mu2>1</mu2>
              </ode>
              <torsional>
                <ode/>
              </torsional>
            </friction>
            <bounce/>
          </surface>
          <max_contacts>10</max_contacts>
        </collision>
        <collision name='bottom'>
          <pose>0 0 0.0127 0 -0 0</pose>
          <geometry>
            <box>
              <size>0.387354 0.387354 0.0254</size>
            </box>
          </geometry>
          <surface>
            <contact>
              <ode>
                <max_vel>0.1</max_vel>
                <min_depth>0.001</min_depth>
              </ode>
            </contact>
            <friction>
              <ode>
                <mu>1</mu>
                <mu2>1</mu2>
              </ode>
              <torsional>
                <ode/>
              </torsional>
            </friction>
            <bounce/>
          </surface>
          <max_contacts>10</max_contacts>
        </collision>
        <collision name='left'>
          <pose>0 -0.183355 0.071438 0 -0 0</pose>
          <geometry>
            <box>
              <size>0.387354 0.020643 0.092075</size>
            </box>
          </geometry>
          <surface>
            <contact>
              <ode>
                <max_vel>0.1</max_vel>
                <min_depth>0.001</min_depth>
              </ode>
            </contact>
            <friction>
              <ode>
                <mu>1</mu>
                <mu2>1</mu2>
              </ode>
              <torsional>
                <ode/>
              </torsional>
            </friction>
            <bounce/>
          </surface>
          <max_contacts>10</max_contacts>
        </collision>
        <collision name='right'>
          <pose>0 0.183355 0.071438 0 -0 0</pose>
          <geometry>
            <box>
              <size>0.387354 0.020643 0.092075</size>
            </box>
          </geometry>
          <surface>
            <contact>
              <ode>
                <max_vel>0.1</max_vel>
                <min_depth>0.001</min_depth>
              </ode>
            </contact>
            <friction>
              <ode>
                <mu>1</mu>
                <mu2>1</mu2>
              </ode>
              <torsional>
                <ode/>
              </torsional>
            </friction>
            <bounce/>
          </surface>
          <max_contacts>10</max_contacts>
        </collision>
        <collision name='middle'>
          <pose>0 0 0.071438 0 -0 0</pose>
          <geometry>
            <box>
              <size>0.387354 0.0254 0.092075</size>
            </box>
          </geometry>
          <surface>
            <contact>
              <ode>
                <max_vel>0.1</max_vel>
                <min_depth>0.001</min_depth>
              </ode>
            </contact>
            <friction>
              <ode>
                <mu>1</mu>
                <mu2>1</mu2>
              </ode>
              <torsional>
                <ode/>
              </torsional>
            </friction>
            <bounce/>
          </surface>
          <max_contacts>10</max_contacts>
        </collision>
        <self_collide>0</self_collide>
        <enable_wind>0</enable_wind>
        <kinematic>0</kinematic>
      </link>
      <pose>-2.42354 -2.88384 0 0 -0 0</pose>
    </model>
    <model name='Mailbox'>
      <link name='link'>
        <collision name='collision'>
          <geometry>
            <mesh>
              <uri>model://mailbox/meshes/mailbox.dae</uri>
            </mesh>
          </geometry>
          <max_contacts>10</max_contacts>
          <surface>
            <contact>
              <ode/>
            </contact>
            <bounce/>
            <friction>
              <torsional>
                <ode/>
              </torsional>
              <ode/>
            </friction>
          </surface>
        </collision>
        <visual name='visual'>
          <geometry>
            <mesh>
              <uri>model://mailbox/meshes/mailbox.dae</uri>
            </mesh>
          </geometry>
          <material>
            <script>
              <uri>model://mailbox/materials/scripts</uri>
              <uri>model://mailbox/materials/textures</uri>
              <name>Mailbox/Diffuse</name>
            </script>
          </material>
        </visual>
        <self_collide>0</self_collide>
        <inertial>
          <pose>0 0 0 0 -0 0</pose>
          <inertia>
            <ixx>1</ixx>
            <ixy>0</ixy>
            <ixz>0</ixz>
            <iyy>1</iyy>
            <iyz>0</iyz>
            <izz>1</izz>
          </inertia>
          <mass>1</mass>
        </inertial>
        <enable_wind>0</enable_wind>
        <kinematic>0</kinematic>
      </link>
      <pose>1.06504 -1.05431 0 0 -0 0</pose>
    </model>
    <model name='textured_shapes'>
      <pose>5.89701 1.17797 0.5 0 -0 0</pose>
      <link name='box'>
        <pose>0 -1.5 0 0 -0 0</pose>
        <collision name='collision'>
          <geometry>
            <box>
              <size>1 1 1</size>
            </box>
          </geometry>
          <max_contacts>10</max_contacts>
          <surface>
            <contact>
              <ode/>
            </contact>
            <bounce/>
            <friction>
              <torsional>
                <ode/>
              </torsional>
              <ode/>
            </friction>
          </surface>
        </collision>
        <visual name='visual'>
          <geometry>
            <box>
              <size>1 1 1</size>
            </box>
          </geometry>
          <material>
            <script>
              <uri>model://textured_shapes/materials/scripts</uri>
              <uri>model://textured_shapes/materials/textures</uri>
              <name>TexturedShape/Squares</name>
            </script>
          </material>
        </visual>
        <self_collide>0</self_collide>
        <inertial>
          <pose>0 0 0 0 -0 0</pose>
          <inertia>
            <ixx>1</ixx>
            <ixy>0</ixy>
            <ixz>0</ixz>
            <iyy>1</iyy>
            <iyz>0</iyz>
            <izz>1</izz>
          </inertia>
          <mass>1</mass>
        </inertial>
        <enable_wind>0</enable_wind>
        <kinematic>0</kinematic>
      </link>
      <link name='sphere'>
        <collision name='collision'>
          <geometry>
            <sphere>
              <radius>0.5</radius>
            </sphere>
          </geometry>
          <max_contacts>10</max_contacts>
          <surface>
            <contact>
              <ode/>
            </contact>
            <bounce/>
            <friction>
              <torsional>
                <ode/>
              </torsional>
              <ode/>
            </friction>
          </surface>
        </collision>
        <visual name='visual'>
          <geometry>
            <sphere>
              <radius>0.5</radius>
            </sphere>
          </geometry>
          <material>
            <script>
              <uri>model://textured_shapes/materials/scripts</uri>
              <uri>model://textured_shapes/materials/textures</uri>
              <name>TexturedShape/Squares</name>
            </script>
          </material>
        </visual>
        <self_collide>0</self_collide>
        <inertial>
          <pose>0 0 0 0 -0 0</pose>
          <inertia>
            <ixx>1</ixx>
            <ixy>0</ixy>
            <ixz>0</ixz>
            <iyy>1</iyy>
            <iyz>0</iyz>
            <izz>1</izz>
          </inertia>
          <mass>1</mass>
        </inertial>
        <enable_wind>0</enable_wind>
        <kinematic>0</kinematic>
      </link>
      <link name='cylinder'>
        <pose>0 1.5 0 0 -0 0</pose>
        <collision name='collision'>
          <geometry>
            <cylinder>
              <radius>0.5</radius>
              <length>1</length>
            </cylinder>
          </geometry>
          <max_contacts>10</max_contacts>
          <surface>
            <contact>
              <ode/>
            </contact>
            <bounce/>
            <friction>
              <torsional>
                <ode/>
              </torsional>
              <ode/>
            </friction>
          </surface>
        </collision>
        <visual name='visual'>
          <geometry>
            <cylinder>
              <radius>0.5</radius>
              <length>1</length>
            </cylinder>
          </geometry>
          <material>
            <script>
              <uri>model://textured_shapes/materials/scripts</uri>
              <uri>model://textured_shapes/materials/textures</uri>
              <name>TexturedShape/Squares</name>
            </script>
          </material>
        </visual>
        <self_collide>0</self_collide>
        <inertial>
          <pose>0 0 0 0 -0 0</pose>
          <inertia>
            <ixx>1</ixx>
            <ixy>0</ixy>
            <ixz>0</ixz>
            <iyy>1</iyy>
            <iyz>0</iyz>
            <izz>1</izz>
          </inertia>
          <mass>1</mass>
        </inertial>
        <enable_wind>0</enable_wind>
        <kinematic>0</kinematic>
      </link>
    </model>
    <model name='first_2015_trash_can'>
      <link name='link'>
        <inertial>
          <pose>0 0 0.3683 0 -0 0</pose>
          <mass>4.83076</mass>
          <inertia>
            <ixx>0.281534</ixx>
            <ixy>0</ixy>
            <ixz>0</ixz>
            <iyy>0.281534</iyy>
            <iyz>0</iyz>
            <izz>0.126223</izz>
          </inertia>
        </inertial>
        <visual name='visual'>
          <geometry>
            <mesh>
              <uri>model://first_2015_trash_can/meshes/trash_can.dae</uri>
            </mesh>
          </geometry>
        </visual>
        <collision name='collision'>
          <geometry>
            <mesh>
              <uri>model://first_2015_trash_can/meshes/trash_can.dae</uri>
            </mesh>
          </geometry>
          <max_contacts>10</max_contacts>
          <surface>
            <contact>
              <ode/>
            </contact>
            <bounce/>
            <friction>
              <torsional>
                <ode/>
              </torsional>
              <ode/>
            </friction>
          </surface>
        </collision>
        <self_collide>0</self_collide>
        <enable_wind>0</enable_wind>
        <kinematic>0</kinematic>
      </link>
      <pose>1.65888 -0.993051 0 0 -0 0</pose>
    </model>
    <model name='fire_hose_long_curled'>
      <pose>2.50727 -0.591063 0.055 0 -0 0</pose>
      <link name='coupling'>
        <inertial>
          <pose>-0.07 0 0 0 -0 0</pose>
          <mass>0.1</mass>
          <inertia>
            <ixx>0.01</ixx>
            <ixy>0</ixy>
            <ixz>0</ixz>
            <iyy>0.01</iyy>
            <iyz>0</iyz>
            <izz>0.01</izz>
          </inertia>
        </inertial>
        <collision name='coupling_collision'>
          <pose>-0.01 0 0 0 -1.57079 0</pose>
          <geometry>
            <mesh>
              <scale>0.4 0.4 0.8</scale>
              <uri>model://fire_hose_long_curled/meshes/coupling_hexagon.dae</uri>
            </mesh>
          </geometry>
          <surface>
            <friction>
              <ode>
                <mu>1</mu>
                <mu2>1</mu2>
              </ode>
              <torsional>
                <ode/>
              </torsional>
            </friction>
            <contact>
              <ode/>
            </contact>
            <bounce/>
          </surface>
          <max_contacts>10</max_contacts>
        </collision>
        <visual name='coupling_vis'>
          <pose>-0.01 0 0 0 -1.57079 0</pose>
          <geometry>
            <mesh>
              <scale>0.4 0.4 0.8</scale>
              <uri>model://fire_hose_long_curled/meshes/coupling_hexagon.dae</uri>
            </mesh>
          </geometry>
          <material>
            <script>
              <uri>model://fire_hose_long_curled/materials/scripts</uri>
              <uri>model://fire_hose_long_curled/materials/textures</uri>
              <name>fire_hose_long_curled/fire_hose_coupling</name>
            </script>
          </material>
        </visual>
        <visual name='attachment_vis'>
          <pose>-0.1225 0 0 0 -1.57079 0</pose>
          <geometry>
            <mesh>
              <uri>model://fire_hose_long_curled/meshes/connector.dae</uri>
            </mesh>
          </geometry>
          <material>
            <script>
              <uri>model://fire_hose_long_curled/materials/scripts</uri>
              <uri>model://fire_hose_long_curled/materials/textures</uri>
              <name>fire_hose_long_curled/fire_hose_red_coupling</name>
            </script>
          </material>
        </visual>
        <collision name='attachment_col'>
          <pose>-0.1225 0 0 0 -1.57079 0</pose>
          <geometry>
            <cylinder>
              <length>0.025</length>
              <radius>0.055</radius>
            </cylinder>
          </geometry>
          <surface>
            <contact>
              <ode>
                <min_depth>0.005</min_depth>
              </ode>
            </contact>
            <friction>
              <ode>
                <mu>1</mu>
                <mu2>1</mu2>
              </ode>
              <torsional>
                <ode/>
              </torsional>
            </friction>
            <bounce/>
          </surface>
          <max_contacts>10</max_contacts>
        </collision>
        <self_collide>0</self_collide>
        <enable_wind>0</enable_wind>
        <kinematic>0</kinematic>
      </link>
      <link name='link_00'>
        <gravity>1</gravity>
        <pose>0.1 0 0 0 -0 0</pose>
        <inertial>
          <mass>0.1</mass>
          <pose>0.1 0 0 0 -0 0</pose>
          <inertia>
            <ixx>0.01</ixx>
            <ixy>0</ixy>
            <ixz>0</ixz>
            <iyy>0.01</iyy>
            <iyz>0</iyz>
            <izz>0.01</izz>
          </inertia>
        </inertial>
        <visual name='sphere'>
          <geometry>
            <sphere>
              <radius>0.025</radius>
            </sphere>
          </geometry>
          <material>
            <script>
              <uri>model://fire_hose_long_curled/materials/scripts</uri>
              <uri>model://fire_hose_long_curled/materials/textures</uri>
              <name>fire_hose_long_curled/fire_hose_canvas</name>
            </script>
          </material>
        </visual>
        <self_collide>0</self_collide>
        <enable_wind>0</enable_wind>
        <kinematic>0</kinematic>
      </link>
      <link name='link_01'>
        <gravity>1</gravity>
        <pose>0.1 0 0 0 -0 0</pose>
        <inertial>
          <mass>0.1</mass>
          <pose>0.1 0 0 0 -0 0</pose>
          <inertia>
            <ixx>0.01</ixx>
            <ixy>0</ixy>
            <ixz>0</ixz>
            <iyy>0.01</iyy>
            <iyz>0</iyz>
            <izz>0.01</izz>
          </inertia>
        </inertial>
        <collision name='collision'>
          <pose>0.1 0 0 0 1.57079 0</pose>
          <geometry>
            <cylinder>
              <length>0.2</length>
              <radius>0.025</radius>
            </cylinder>
          </geometry>
          <surface>
            <contact>
              <ode>
                <min_depth>0.005</min_depth>
              </ode>
            </contact>
            <friction>
              <ode>
                <mu>1</mu>
                <mu2>1</mu2>
              </ode>
              <torsional>
                <ode/>
              </torsional>
            </friction>
            <bounce/>
          </surface>
          <max_contacts>10</max_contacts>
        </collision>
        <visual name='visual'>
          <pose>0.1 0 0 0 1.57079 0</pose>
          <geometry>
            <cylinder>
              <length>0.2</length>
              <radius>0.025</radius>
            </cylinder>
          </geometry>
          <material>
            <script>
              <uri>model://fire_hose_long_curled/materials/scripts</uri>
              <uri>model://fire_hose_long_curled/materials/textures</uri>
              <name>fire_hose_long_curled/fire_hose_canvas</name>
            </script>
          </material>
        </visual>
        <self_collide>0</self_collide>
        <enable_wind>0</enable_wind>
        <kinematic>0</kinematic>
      </link>
      <link name='link_02'>
        <gravity>1</gravity>
        <pose>0.3 0 0 0 -0 0</pose>
        <inertial>
          <mass>0.1</mass>
          <pose>0.1 0 0 0 -0 0</pose>
          <inertia>
            <ixx>0.01</ixx>
            <ixy>0</ixy>
            <ixz>0</ixz>
            <iyy>0.01</iyy>
            <iyz>0</iyz>
            <izz>0.01</izz>
          </inertia>
        </inertial>
        <collision name='collision'>
          <pose>0.1 0 0 0 1.57079 0</pose>
          <geometry>
            <cylinder>
              <length>0.2</length>
              <radius>0.025</radius>
            </cylinder>
          </geometry>
          <surface>
            <contact>
              <ode>
                <min_depth>0.005</min_depth>
              </ode>
            </contact>
            <friction>
              <ode>
                <mu>1</mu>
                <mu2>1</mu2>
              </ode>
              <torsional>
                <ode/>
              </torsional>
            </friction>
            <bounce/>
          </surface>
          <max_contacts>10</max_contacts>
        </collision>
        <visual name='visual'>
          <pose>0.1 0 0 0 1.57079 0</pose>
          <geometry>
            <cylinder>
              <length>0.2</length>
              <radius>0.025</radius>
            </cylinder>
          </geometry>
          <material>
            <script>
              <uri>model://fire_hose_long_curled/materials/scripts</uri>
              <uri>model://fire_hose_long_curled/materials/textures</uri>
              <name>fire_hose_long_curled/fire_hose_canvas</name>
            </script>
          </material>
        </visual>
        <visual name='sphere'>
          <geometry>
            <sphere>
              <radius>0.025</radius>
            </sphere>
          </geometry>
          <material>
            <script>
              <uri>model://fire_hose_long_curled/materials/scripts</uri>
              <uri>model://fire_hose_long_curled/materials/textures</uri>
              <name>fire_hose_long_curled/fire_hose_canvas</name>
            </script>
          </material>
        </visual>
        <self_collide>0</self_collide>
        <enable_wind>0</enable_wind>
        <kinematic>0</kinematic>
      </link>
      <link name='link_03'>
        <gravity>1</gravity>
        <pose>0.5 0 0 0 -0 0</pose>
        <inertial>
          <mass>0.1</mass>
          <pose>0.1 0 0 0 -0 0</pose>
          <inertia>
            <ixx>0.01</ixx>
            <ixy>0</ixy>
            <ixz>0</ixz>
            <iyy>0.01</iyy>
            <iyz>0</iyz>
            <izz>0.01</izz>
          </inertia>
        </inertial>
        <collision name='collision'>
          <pose>0.1 0 0 0 1.57079 0</pose>
          <geometry>
            <cylinder>
              <length>0.2</length>
              <radius>0.025</radius>
            </cylinder>
          </geometry>
          <surface>
            <contact>
              <ode>
                <min_depth>0.005</min_depth>
              </ode>
            </contact>
            <friction>
              <ode>
                <mu>1</mu>
                <mu2>1</mu2>
              </ode>
              <torsional>
                <ode/>
              </torsional>
            </friction>
            <bounce/>
          </surface>
          <max_contacts>10</max_contacts>
        </collision>
        <visual name='visual'>
          <pose>0.1 0 0 0 1.57079 0</pose>
          <geometry>
            <cylinder>
              <length>0.2</length>
              <radius>0.025</radius>
            </cylinder>
          </geometry>
          <material>
            <script>
              <uri>model://fire_hose_long_curled/materials/scripts</uri>
              <uri>model://fire_hose_long_curled/materials/textures</uri>
              <name>fire_hose_long_curled/fire_hose_canvas</name>
            </script>
          </material>
        </visual>
        <visual name='sphere'>
          <geometry>
            <sphere>
              <radius>0.025</radius>
            </sphere>
          </geometry>
          <material>
            <script>
              <uri>model://fire_hose_long_curled/materials/scripts</uri>
              <uri>model://fire_hose_long_curled/materials/textures</uri>
              <name>fire_hose_long_curled/fire_hose_canvas</name>
            </script>
          </material>
        </visual>
        <self_collide>0</self_collide>
        <enable_wind>0</enable_wind>
        <kinematic>0</kinematic>
      </link>
      <link name='link_04'>
        <gravity>1</gravity>
        <pose>0.7 0 0 0 -0 0</pose>
        <inertial>
          <mass>0.1</mass>
          <pose>0.1 0 0 0 -0 0</pose>
          <inertia>
            <ixx>0.01</ixx>
            <ixy>0</ixy>
            <ixz>0</ixz>
            <iyy>0.01</iyy>
            <iyz>0</iyz>
            <izz>0.01</izz>
          </inertia>
        </inertial>
        <collision name='collision'>
          <pose>0.1 0 0 0 1.57079 0</pose>
          <geometry>
            <cylinder>
              <length>0.2</length>
              <radius>0.025</radius>
            </cylinder>
          </geometry>
          <surface>
            <contact>
              <ode>
                <min_depth>0.005</min_depth>
              </ode>
            </contact>
            <friction>
              <ode>
                <mu>1</mu>
                <mu2>1</mu2>
              </ode>
              <torsional>
                <ode/>
              </torsional>
            </friction>
            <bounce/>
          </surface>
          <max_contacts>10</max_contacts>
        </collision>
        <visual name='visual'>
          <pose>0.1 0 0 0 1.57079 0</pose>
          <geometry>
            <cylinder>
              <length>0.2</length>
              <radius>0.025</radius>
            </cylinder>
          </geometry>
          <material>
            <script>
              <uri>model://fire_hose_long_curled/materials/scripts</uri>
              <uri>model://fire_hose_long_curled/materials/textures</uri>
              <name>fire_hose_long_curled/fire_hose_canvas</name>
            </script>
          </material>
        </visual>
        <visual name='sphere'>
          <geometry>
            <sphere>
              <radius>0.025</radius>
            </sphere>
          </geometry>
          <material>
            <script>
              <uri>model://fire_hose_long_curled/materials/scripts</uri>
              <uri>model://fire_hose_long_curled/materials/textures</uri>
              <name>fire_hose_long_curled/fire_hose_canvas</name>
            </script>
          </material>
        </visual>
        <self_collide>0</self_collide>
        <enable_wind>0</enable_wind>
        <kinematic>0</kinematic>
      </link>
      <link name='link_05'>
        <gravity>1</gravity>
        <pose>0.9 0 0 0 -0 0</pose>
        <inertial>
          <mass>0.1</mass>
          <pose>0.1 0 0 0 -0 0</pose>
          <inertia>
            <ixx>0.01</ixx>
            <ixy>0</ixy>
            <ixz>0</ixz>
            <iyy>0.01</iyy>
            <iyz>0</iyz>
            <izz>0.01</izz>
          </inertia>
        </inertial>
        <collision name='collision'>
          <pose>0.1 0 0 0 1.57079 0</pose>
          <geometry>
            <cylinder>
              <length>0.2</length>
              <radius>0.025</radius>
            </cylinder>
          </geometry>
          <surface>
            <contact>
              <ode>
                <min_depth>0.005</min_depth>
              </ode>
            </contact>
            <friction>
              <ode>
                <mu>1</mu>
                <mu2>1</mu2>
              </ode>
              <torsional>
                <ode/>
              </torsional>
            </friction>
            <bounce/>
          </surface>
          <max_contacts>10</max_contacts>
        </collision>
        <visual name='visual'>
          <pose>0.1 0 0 0 1.57079 0</pose>
          <geometry>
            <cylinder>
              <length>0.2</length>
              <radius>0.025</radius>
            </cylinder>
          </geometry>
          <material>
            <script>
              <uri>model://fire_hose_long_curled/materials/scripts</uri>
              <uri>model://fire_hose_long_curled/materials/textures</uri>
              <name>fire_hose_long_curled/fire_hose_canvas</name>
            </script>
          </material>
        </visual>
        <visual name='sphere'>
          <geometry>
            <sphere>
              <radius>0.025</radius>
            </sphere>
          </geometry>
          <material>
            <script>
              <uri>model://fire_hose_long_curled/materials/scripts</uri>
              <uri>model://fire_hose_long_curled/materials/textures</uri>
              <name>fire_hose_long_curled/fire_hose_canvas</name>
            </script>
          </material>
        </visual>
        <self_collide>0</self_collide>
        <enable_wind>0</enable_wind>
        <kinematic>0</kinematic>
      </link>
      <link name='link_06'>
        <gravity>1</gravity>
        <pose>1.1 0 0 0 0 -0.785</pose>
        <inertial>
          <mass>0.1</mass>
          <pose>0.0875 0 0 0 -0 0</pose>
          <inertia>
            <ixx>0.01</ixx>
            <ixy>0</ixy>
            <ixz>0</ixz>
            <iyy>0.01</iyy>
            <iyz>0</iyz>
            <izz>0.01</izz>
          </inertia>
        </inertial>
        <collision name='collision'>
          <pose>0.0875 0 0 0 1.57079 0</pose>
          <geometry>
            <cylinder>
              <length>0.175</length>
              <radius>0.025</radius>
            </cylinder>
          </geometry>
          <surface>
            <contact>
              <ode>
                <min_depth>0.005</min_depth>
              </ode>
            </contact>
            <friction>
              <ode>
                <mu>1</mu>
                <mu2>1</mu2>
              </ode>
              <torsional>
                <ode/>
              </torsional>
            </friction>
            <bounce/>
          </surface>
          <max_contacts>10</max_contacts>
        </collision>
        <visual name='visual'>
          <pose>0.0875 0 0 0 1.57079 0</pose>
          <geometry>
            <cylinder>
              <length>0.175</length>
              <radius>0.025</radius>
            </cylinder>
          </geometry>
          <material>
            <script>
              <uri>model://fire_hose_long_curled/materials/scripts</uri>
              <uri>model://fire_hose_long_curled/materials/textures</uri>
              <name>fire_hose_long_curled/fire_hose_canvas</name>
            </script>
          </material>
        </visual>
        <visual name='sphere'>
          <geometry>
            <sphere>
              <radius>0.025</radius>
            </sphere>
          </geometry>
          <material>
            <script>
              <uri>model://fire_hose_long_curled/materials/scripts</uri>
              <uri>model://fire_hose_long_curled/materials/textures</uri>
              <name>fire_hose_long_curled/fire_hose_canvas</name>
            </script>
          </material>
        </visual>
        <self_collide>0</self_collide>
        <enable_wind>0</enable_wind>
        <kinematic>0</kinematic>
      </link>
      <link name='link_07'>
        <gravity>1</gravity>
        <pose>1.227 -0.127 0 0 0 -2.3415</pose>
        <inertial>
          <mass>0.1</mass>
          <pose>0.0875 0 0 0 -0 0</pose>
          <inertia>
            <ixx>0.01</ixx>
            <ixy>0</ixy>
            <ixz>0</ixz>
            <iyy>0.01</iyy>
            <iyz>0</iyz>
            <izz>0.01</izz>
          </inertia>
        </inertial>
        <collision name='collision'>
          <pose>0.0875 0 0 0 1.57079 0</pose>
          <geometry>
            <cylinder>
              <length>0.175</length>
              <radius>0.025</radius>
            </cylinder>
          </geometry>
          <surface>
            <contact>
              <ode>
                <min_depth>0.005</min_depth>
              </ode>
            </contact>
            <friction>
              <ode>
                <mu>1</mu>
                <mu2>1</mu2>
              </ode>
              <torsional>
                <ode/>
              </torsional>
            </friction>
            <bounce/>
          </surface>
          <max_contacts>10</max_contacts>
        </collision>
        <visual name='visual'>
          <pose>0.0875 0 0 0 1.57079 0</pose>
          <geometry>
            <cylinder>
              <length>0.175</length>
              <radius>0.025</radius>
            </cylinder>
          </geometry>
          <material>
            <script>
              <uri>model://fire_hose_long_curled/materials/scripts</uri>
              <uri>model://fire_hose_long_curled/materials/textures</uri>
              <name>fire_hose_long_curled/fire_hose_canvas</name>
            </script>
          </material>
        </visual>
        <visual name='sphere'>
          <geometry>
            <sphere>
              <radius>0.025</radius>
            </sphere>
          </geometry>
          <material>
            <script>
              <uri>model://fire_hose_long_curled/materials/scripts</uri>
              <uri>model://fire_hose_long_curled/materials/textures</uri>
              <name>fire_hose_long_curled/fire_hose_canvas</name>
            </script>
          </material>
        </visual>
        <self_collide>0</self_collide>
        <enable_wind>0</enable_wind>
        <kinematic>0</kinematic>
      </link>
      <link name='link_08'>
        <gravity>1</gravity>
        <pose>1.1 -0.254 0 0 0 -3.1415</pose>
        <inertial>
          <mass>0.1</mass>
          <pose>0.1 0 0 0 -0 0</pose>
          <inertia>
            <ixx>0.01</ixx>
            <ixy>0</ixy>
            <ixz>0</ixz>
            <iyy>0.01</iyy>
            <iyz>0</iyz>
            <izz>0.01</izz>
          </inertia>
        </inertial>
        <collision name='collision'>
          <pose>0.1 0 0 0 1.57079 0</pose>
          <geometry>
            <cylinder>
              <length>0.2</length>
              <radius>0.025</radius>
            </cylinder>
          </geometry>
          <surface>
            <contact>
              <ode>
                <min_depth>0.005</min_depth>
              </ode>
            </contact>
            <friction>
              <ode>
                <mu>1</mu>
                <mu2>1</mu2>
              </ode>
              <torsional>
                <ode/>
              </torsional>
            </friction>
            <bounce/>
          </surface>
          <max_contacts>10</max_contacts>
        </collision>
        <visual name='visual'>
          <pose>0.1 0 0 0 1.57079 0</pose>
          <geometry>
            <cylinder>
              <length>0.2</length>
              <radius>0.025</radius>
            </cylinder>
          </geometry>
          <material>
            <script>
              <uri>model://fire_hose_long_curled/materials/scripts</uri>
              <uri>model://fire_hose_long_curled/materials/textures</uri>
              <name>fire_hose_long_curled/fire_hose_canvas</name>
            </script>
          </material>
        </visual>
        <visual name='sphere'>
          <geometry>
            <sphere>
              <radius>0.025</radius>
            </sphere>
          </geometry>
          <material>
            <script>
              <uri>model://fire_hose_long_curled/materials/scripts</uri>
              <uri>model://fire_hose_long_curled/materials/textures</uri>
              <name>fire_hose_long_curled/fire_hose_canvas</name>
            </script>
          </material>
        </visual>
        <self_collide>0</self_collide>
        <enable_wind>0</enable_wind>
        <kinematic>0</kinematic>
      </link>
      <link name='link_09'>
        <gravity>1</gravity>
        <pose>0.9 -0.254 0 0 0 -3.1415</pose>
        <inertial>
          <mass>0.1</mass>
          <pose>0.1 0 0 0 -0 0</pose>
          <inertia>
            <ixx>0.01</ixx>
            <ixy>0</ixy>
            <ixz>0</ixz>
            <iyy>0.01</iyy>
            <iyz>0</iyz>
            <izz>0.01</izz>
          </inertia>
        </inertial>
        <collision name='collision'>
          <pose>0.1 0 0 0 1.57079 0</pose>
          <geometry>
            <cylinder>
              <length>0.2</length>
              <radius>0.025</radius>
            </cylinder>
          </geometry>
          <surface>
            <contact>
              <ode>
                <min_depth>0.005</min_depth>
              </ode>
            </contact>
            <friction>
              <ode>
                <mu>1</mu>
                <mu2>1</mu2>
              </ode>
              <torsional>
                <ode/>
              </torsional>
            </friction>
            <bounce/>
          </surface>
          <max_contacts>10</max_contacts>
        </collision>
        <visual name='visual'>
          <pose>0.1 0 0 0 1.57079 0</pose>
          <geometry>
            <cylinder>
              <length>0.2</length>
              <radius>0.025</radius>
            </cylinder>
          </geometry>
          <material>
            <script>
              <uri>model://fire_hose_long_curled/materials/scripts</uri>
              <uri>model://fire_hose_long_curled/materials/textures</uri>
              <name>fire_hose_long_curled/fire_hose_canvas</name>
            </script>
          </material>
        </visual>
        <visual name='sphere'>
          <geometry>
            <sphere>
              <radius>0.025</radius>
            </sphere>
          </geometry>
          <material>
            <script>
              <uri>model://fire_hose_long_curled/materials/scripts</uri>
              <uri>model://fire_hose_long_curled/materials/textures</uri>
              <name>fire_hose_long_curled/fire_hose_canvas</name>
            </script>
          </material>
        </visual>
        <self_collide>0</self_collide>
        <enable_wind>0</enable_wind>
        <kinematic>0</kinematic>
      </link>
      <link name='link_10'>
        <gravity>1</gravity>
        <pose>0.7 -0.254 0 0 0 -3.1415</pose>
        <inertial>
          <mass>0.1</mass>
          <pose>0.1 0 0 0 -0 0</pose>
          <inertia>
            <ixx>0.01</ixx>
            <ixy>0</ixy>
            <ixz>0</ixz>
            <iyy>0.01</iyy>
            <iyz>0</iyz>
            <izz>0.01</izz>
          </inertia>
        </inertial>
        <collision name='collision'>
          <pose>0.1 0 0 0 1.57079 0</pose>
          <geometry>
            <cylinder>
              <length>0.2</length>
              <radius>0.025</radius>
            </cylinder>
          </geometry>
          <surface>
            <contact>
              <ode>
                <min_depth>0.005</min_depth>
              </ode>
            </contact>
            <friction>
              <ode>
                <mu>1</mu>
                <mu2>1</mu2>
              </ode>
              <torsional>
                <ode/>
              </torsional>
            </friction>
            <bounce/>
          </surface>
          <max_contacts>10</max_contacts>
        </collision>
        <visual name='visual'>
          <pose>0.1 0 0 0 1.57079 0</pose>
          <geometry>
            <cylinder>
              <length>0.2</length>
              <radius>0.025</radius>
            </cylinder>
          </geometry>
          <material>
            <script>
              <uri>model://fire_hose_long_curled/materials/scripts</uri>
              <uri>model://fire_hose_long_curled/materials/textures</uri>
              <name>fire_hose_long_curled/fire_hose_canvas</name>
            </script>
          </material>
        </visual>
        <visual name='sphere'>
          <geometry>
            <sphere>
              <radius>0.025</radius>
            </sphere>
          </geometry>
          <material>
            <script>
              <uri>model://fire_hose_long_curled/materials/scripts</uri>
              <uri>model://fire_hose_long_curled/materials/textures</uri>
              <name>fire_hose_long_curled/fire_hose_canvas</name>
            </script>
          </material>
        </visual>
        <self_collide>0</self_collide>
        <enable_wind>0</enable_wind>
        <kinematic>0</kinematic>
      </link>
      <link name='link_11'>
        <gravity>1</gravity>
        <pose>0.5 -0.254 0 0 0 -3.1415</pose>
        <inertial>
          <mass>0.1</mass>
          <pose>0.1 0 0 0 -0 0</pose>
          <inertia>
            <ixx>0.01</ixx>
            <ixy>0</ixy>
            <ixz>0</ixz>
            <iyy>0.01</iyy>
            <iyz>0</iyz>
            <izz>0.01</izz>
          </inertia>
        </inertial>
        <collision name='collision'>
          <pose>0.1 0 0 0 1.57079 0</pose>
          <geometry>
            <cylinder>
              <length>0.2</length>
              <radius>0.025</radius>
            </cylinder>
          </geometry>
          <surface>
            <contact>
              <ode>
                <min_depth>0.005</min_depth>
              </ode>
            </contact>
            <friction>
              <ode>
                <mu>1</mu>
                <mu2>1</mu2>
              </ode>
              <torsional>
                <ode/>
              </torsional>
            </friction>
            <bounce/>
          </surface>
          <max_contacts>10</max_contacts>
        </collision>
        <visual name='visual'>
          <pose>0.1 0 0 0 1.57079 0</pose>
          <geometry>
            <cylinder>
              <length>0.2</length>
              <radius>0.025</radius>
            </cylinder>
          </geometry>
          <material>
            <script>
              <uri>model://fire_hose_long_curled/materials/scripts</uri>
              <uri>model://fire_hose_long_curled/materials/textures</uri>
              <name>fire_hose_long_curled/fire_hose_canvas</name>
            </script>
          </material>
        </visual>
        <visual name='sphere'>
          <geometry>
            <sphere>
              <radius>0.025</radius>
            </sphere>
          </geometry>
          <material>
            <script>
              <uri>model://fire_hose_long_curled/materials/scripts</uri>
              <uri>model://fire_hose_long_curled/materials/textures</uri>
              <name>fire_hose_long_curled/fire_hose_canvas</name>
            </script>
          </material>
        </visual>
        <self_collide>0</self_collide>
        <enable_wind>0</enable_wind>
        <kinematic>0</kinematic>
      </link>
      <link name='link_12'>
        <gravity>1</gravity>
        <pose>0.3 -0.254 0 0 0 -3.1415</pose>
        <inertial>
          <mass>0.1</mass>
          <pose>0.1 0 0 0 -0 0</pose>
          <inertia>
            <ixx>0.01</ixx>
            <ixy>0</ixy>
            <ixz>0</ixz>
            <iyy>0.01</iyy>
            <iyz>0</iyz>
            <izz>0.01</izz>
          </inertia>
        </inertial>
        <collision name='collision'>
          <pose>0.1 0 0 0 1.57079 0</pose>
          <geometry>
            <cylinder>
              <length>0.2</length>
              <radius>0.025</radius>
            </cylinder>
          </geometry>
          <surface>
            <contact>
              <ode>
                <min_depth>0.005</min_depth>
              </ode>
            </contact>
            <friction>
              <ode>
                <mu>1</mu>
                <mu2>1</mu2>
              </ode>
              <torsional>
                <ode/>
              </torsional>
            </friction>
            <bounce/>
          </surface>
          <max_contacts>10</max_contacts>
        </collision>
        <visual name='visual'>
          <pose>0.1 0 0 0 1.57079 0</pose>
          <geometry>
            <cylinder>
              <length>0.2</length>
              <radius>0.025</radius>
            </cylinder>
          </geometry>
          <material>
            <script>
              <uri>model://fire_hose_long_curled/materials/scripts</uri>
              <uri>model://fire_hose_long_curled/materials/textures</uri>
              <name>fire_hose_long_curled/fire_hose_canvas</name>
            </script>
          </material>
        </visual>
        <visual name='sphere'>
          <geometry>
            <sphere>
              <radius>0.025</radius>
            </sphere>
          </geometry>
          <material>
            <script>
              <uri>model://fire_hose_long_curled/materials/scripts</uri>
              <uri>model://fire_hose_long_curled/materials/textures</uri>
              <name>fire_hose_long_curled/fire_hose_canvas</name>
            </script>
          </material>
        </visual>
        <self_collide>0</self_collide>
        <enable_wind>0</enable_wind>
        <kinematic>0</kinematic>
      </link>
      <link name='link_13'>
        <gravity>1</gravity>
        <pose>0.1 -0.254 0 0 0 -2.356</pose>
        <inertial>
          <mass>0.1</mass>
          <pose>0.0875 0 0 0 -0 0</pose>
          <inertia>
            <ixx>0.01</ixx>
            <ixy>0</ixy>
            <ixz>0</ixz>
            <iyy>0.01</iyy>
            <iyz>0</iyz>
            <izz>0.01</izz>
          </inertia>
        </inertial>
        <collision name='collision'>
          <pose>0.0875 0 0 0 1.57079 0</pose>
          <geometry>
            <cylinder>
              <length>0.175</length>
              <radius>0.025</radius>
            </cylinder>
          </geometry>
          <surface>
            <contact>
              <ode>
                <min_depth>0.005</min_depth>
              </ode>
            </contact>
            <friction>
              <ode>
                <mu>1</mu>
                <mu2>1</mu2>
              </ode>
              <torsional>
                <ode/>
              </torsional>
            </friction>
            <bounce/>
          </surface>
          <max_contacts>10</max_contacts>
        </collision>
        <visual name='visual'>
          <pose>0.0875 0 0 0 1.57079 0</pose>
          <geometry>
            <cylinder>
              <length>0.175</length>
              <radius>0.025</radius>
            </cylinder>
          </geometry>
          <material>
            <script>
              <uri>model://fire_hose_long_curled/materials/scripts</uri>
              <uri>model://fire_hose_long_curled/materials/textures</uri>
              <name>fire_hose_long_curled/fire_hose_canvas</name>
            </script>
          </material>
        </visual>
        <visual name='sphere'>
          <geometry>
            <sphere>
              <radius>0.025</radius>
            </sphere>
          </geometry>
          <material>
            <script>
              <uri>model://fire_hose_long_curled/materials/scripts</uri>
              <uri>model://fire_hose_long_curled/materials/textures</uri>
              <name>fire_hose_long_curled/fire_hose_canvas</name>
            </script>
          </material>
        </visual>
        <self_collide>0</self_collide>
        <enable_wind>0</enable_wind>
        <kinematic>0</kinematic>
      </link>
      <link name='link_14'>
        <gravity>1</gravity>
        <pose>-0.027 -0.381 0 0 0 -0.785</pose>
        <inertial>
          <mass>0.1</mass>
          <pose>0.0875 0 0 0 -0 0</pose>
          <inertia>
            <ixx>0.01</ixx>
            <ixy>0</ixy>
            <ixz>0</ixz>
            <iyy>0.01</iyy>
            <iyz>0</iyz>
            <izz>0.01</izz>
          </inertia>
        </inertial>
        <collision name='collision'>
          <pose>0.0875 0 0 0 1.57079 0</pose>
          <geometry>
            <cylinder>
              <length>0.175</length>
              <radius>0.025</radius>
            </cylinder>
          </geometry>
          <surface>
            <contact>
              <ode>
                <min_depth>0.005</min_depth>
              </ode>
            </contact>
            <friction>
              <ode>
                <mu>1</mu>
                <mu2>1</mu2>
              </ode>
              <torsional>
                <ode/>
              </torsional>
            </friction>
            <bounce/>
          </surface>
          <max_contacts>10</max_contacts>
        </collision>
        <visual name='visual'>
          <pose>0.0875 0 0 0 1.57079 0</pose>
          <geometry>
            <cylinder>
              <length>0.175</length>
              <radius>0.025</radius>
            </cylinder>
          </geometry>
          <material>
            <script>
              <uri>model://fire_hose_long_curled/materials/scripts</uri>
              <uri>model://fire_hose_long_curled/materials/textures</uri>
              <name>fire_hose_long_curled/fire_hose_canvas</name>
            </script>
          </material>
        </visual>
        <visual name='sphere'>
          <geometry>
            <sphere>
              <radius>0.025</radius>
            </sphere>
          </geometry>
          <material>
            <script>
              <uri>model://fire_hose_long_curled/materials/scripts</uri>
              <uri>model://fire_hose_long_curled/materials/textures</uri>
              <name>fire_hose_long_curled/fire_hose_canvas</name>
            </script>
          </material>
        </visual>
        <self_collide>0</self_collide>
        <enable_wind>0</enable_wind>
        <kinematic>0</kinematic>
      </link>
      <link name='link_15'>
        <gravity>1</gravity>
        <pose>0.1 -0.508 0 0 -0 0</pose>
        <inertial>
          <mass>0.1</mass>
          <pose>0.1 0 0 0 -0 0</pose>
          <inertia>
            <ixx>0.01</ixx>
            <ixy>0</ixy>
            <ixz>0</ixz>
            <iyy>0.01</iyy>
            <iyz>0</iyz>
            <izz>0.01</izz>
          </inertia>
        </inertial>
        <collision name='collision'>
          <pose>0.1 0 0 0 1.57079 0</pose>
          <geometry>
            <cylinder>
              <length>0.2</length>
              <radius>0.025</radius>
            </cylinder>
          </geometry>
          <surface>
            <contact>
              <ode>
                <min_depth>0.005</min_depth>
              </ode>
            </contact>
            <friction>
              <ode>
                <mu>1</mu>
                <mu2>1</mu2>
              </ode>
              <torsional>
                <ode/>
              </torsional>
            </friction>
            <bounce/>
          </surface>
          <max_contacts>10</max_contacts>
        </collision>
        <visual name='visual'>
          <pose>0.1 0 0 0 1.57079 0</pose>
          <geometry>
            <cylinder>
              <length>0.2</length>
              <radius>0.025</radius>
            </cylinder>
          </geometry>
          <material>
            <script>
              <uri>model://fire_hose_long_curled/materials/scripts</uri>
              <uri>model://fire_hose_long_curled/materials/textures</uri>
              <name>fire_hose_long_curled/fire_hose_canvas</name>
            </script>
          </material>
        </visual>
        <visual name='sphere'>
          <geometry>
            <sphere>
              <radius>0.025</radius>
            </sphere>
          </geometry>
          <material>
            <script>
              <uri>model://fire_hose_long_curled/materials/scripts</uri>
              <uri>model://fire_hose_long_curled/materials/textures</uri>
              <name>fire_hose_long_curled/fire_hose_canvas</name>
            </script>
          </material>
        </visual>
        <self_collide>0</self_collide>
        <enable_wind>0</enable_wind>
        <kinematic>0</kinematic>
      </link>
      <link name='link_16'>
        <gravity>1</gravity>
        <pose>0.3 -0.508 0 0 -0 0</pose>
        <inertial>
          <mass>0.1</mass>
          <pose>0.1 0 0 0 -0 0</pose>
          <inertia>
            <ixx>0.01</ixx>
            <ixy>0</ixy>
            <ixz>0</ixz>
            <iyy>0.01</iyy>
            <iyz>0</iyz>
            <izz>0.01</izz>
          </inertia>
        </inertial>
        <collision name='collision'>
          <pose>0.1 0 0 0 1.57079 0</pose>
          <geometry>
            <cylinder>
              <length>0.2</length>
              <radius>0.025</radius>
            </cylinder>
          </geometry>
          <surface>
            <contact>
              <ode>
                <min_depth>0.005</min_depth>
              </ode>
            </contact>
            <friction>
              <ode>
                <mu>1</mu>
                <mu2>1</mu2>
              </ode>
              <torsional>
                <ode/>
              </torsional>
            </friction>
            <bounce/>
          </surface>
          <max_contacts>10</max_contacts>
        </collision>
        <visual name='visual'>
          <pose>0.1 0 0 0 1.57079 0</pose>
          <geometry>
            <cylinder>
              <length>0.2</length>
              <radius>0.025</radius>
            </cylinder>
          </geometry>
          <material>
            <script>
              <uri>model://fire_hose_long_curled/materials/scripts</uri>
              <uri>model://fire_hose_long_curled/materials/textures</uri>
              <name>fire_hose_long_curled/fire_hose_canvas</name>
            </script>
          </material>
        </visual>
        <visual name='sphere'>
          <geometry>
            <sphere>
              <radius>0.025</radius>
            </sphere>
          </geometry>
          <material>
            <script>
              <uri>model://fire_hose_long_curled/materials/scripts</uri>
              <uri>model://fire_hose_long_curled/materials/textures</uri>
              <name>fire_hose_long_curled/fire_hose_canvas</name>
            </script>
          </material>
        </visual>
        <self_collide>0</self_collide>
        <enable_wind>0</enable_wind>
        <kinematic>0</kinematic>
      </link>
      <link name='link_17'>
        <gravity>1</gravity>
        <pose>0.5 -0.508 0 0 -0 0</pose>
        <inertial>
          <mass>0.1</mass>
          <pose>0.1 0 0 0 -0 0</pose>
          <inertia>
            <ixx>0.01</ixx>
            <ixy>0</ixy>
            <ixz>0</ixz>
            <iyy>0.01</iyy>
            <iyz>0</iyz>
            <izz>0.01</izz>
          </inertia>
        </inertial>
        <collision name='collision'>
          <pose>0.1 0 0 0 1.57079 0</pose>
          <geometry>
            <cylinder>
              <length>0.2</length>
              <radius>0.025</radius>
            </cylinder>
          </geometry>
          <surface>
            <contact>
              <ode>
                <min_depth>0.005</min_depth>
              </ode>
            </contact>
            <friction>
              <ode>
                <mu>1</mu>
                <mu2>1</mu2>
              </ode>
              <torsional>
                <ode/>
              </torsional>
            </friction>
            <bounce/>
          </surface>
          <max_contacts>10</max_contacts>
        </collision>
        <visual name='visual'>
          <pose>0.1 0 0 0 1.57079 0</pose>
          <geometry>
            <cylinder>
              <length>0.2</length>
              <radius>0.025</radius>
            </cylinder>
          </geometry>
          <material>
            <script>
              <uri>model://fire_hose_long_curled/materials/scripts</uri>
              <uri>model://fire_hose_long_curled/materials/textures</uri>
              <name>fire_hose_long_curled/fire_hose_canvas</name>
            </script>
          </material>
        </visual>
        <visual name='sphere'>
          <geometry>
            <sphere>
              <radius>0.025</radius>
            </sphere>
          </geometry>
          <material>
            <script>
              <uri>model://fire_hose_long_curled/materials/scripts</uri>
              <uri>model://fire_hose_long_curled/materials/textures</uri>
              <name>fire_hose_long_curled/fire_hose_canvas</name>
            </script>
          </material>
        </visual>
        <self_collide>0</self_collide>
        <enable_wind>0</enable_wind>
        <kinematic>0</kinematic>
      </link>
      <link name='link_18'>
        <gravity>1</gravity>
        <pose>0.7 -0.508 0 0 -0 0</pose>
        <inertial>
          <mass>0.1</mass>
          <pose>0.1 0 0 0 -0 0</pose>
          <inertia>
            <ixx>0.01</ixx>
            <ixy>0</ixy>
            <ixz>0</ixz>
            <iyy>0.01</iyy>
            <iyz>0</iyz>
            <izz>0.01</izz>
          </inertia>
        </inertial>
        <collision name='collision'>
          <pose>0.1 0 0 0 1.57079 0</pose>
          <geometry>
            <cylinder>
              <length>0.2</length>
              <radius>0.025</radius>
            </cylinder>
          </geometry>
          <surface>
            <contact>
              <ode>
                <min_depth>0.005</min_depth>
              </ode>
            </contact>
            <friction>
              <ode>
                <mu>1</mu>
                <mu2>1</mu2>
              </ode>
              <torsional>
                <ode/>
              </torsional>
            </friction>
            <bounce/>
          </surface>
          <max_contacts>10</max_contacts>
        </collision>
        <visual name='visual'>
          <pose>0.1 0 0 0 1.57079 0</pose>
          <geometry>
            <cylinder>
              <length>0.2</length>
              <radius>0.025</radius>
            </cylinder>
          </geometry>
          <material>
            <script>
              <uri>model://fire_hose_long_curled/materials/scripts</uri>
              <uri>model://fire_hose_long_curled/materials/textures</uri>
              <name>fire_hose_long_curled/fire_hose_canvas</name>
            </script>
          </material>
        </visual>
        <visual name='sphere'>
          <geometry>
            <sphere>
              <radius>0.025</radius>
            </sphere>
          </geometry>
          <material>
            <script>
              <uri>model://fire_hose_long_curled/materials/scripts</uri>
              <uri>model://fire_hose_long_curled/materials/textures</uri>
              <name>fire_hose_long_curled/fire_hose_canvas</name>
            </script>
          </material>
        </visual>
        <self_collide>0</self_collide>
        <enable_wind>0</enable_wind>
        <kinematic>0</kinematic>
      </link>
      <link name='link_19'>
        <gravity>1</gravity>
        <pose>0.9 -0.508 0 0 -0 0</pose>
        <inertial>
          <mass>0.1</mass>
          <pose>0.1 0 0 0 -0 0</pose>
          <inertia>
            <ixx>0.01</ixx>
            <ixy>0</ixy>
            <ixz>0</ixz>
            <iyy>0.01</iyy>
            <iyz>0</iyz>
            <izz>0.01</izz>
          </inertia>
        </inertial>
        <collision name='collision'>
          <pose>0.1 0 0 0 1.57079 0</pose>
          <geometry>
            <cylinder>
              <length>0.2</length>
              <radius>0.025</radius>
            </cylinder>
          </geometry>
          <surface>
            <contact>
              <ode>
                <min_depth>0.005</min_depth>
              </ode>
            </contact>
            <friction>
              <ode>
                <mu>1</mu>
                <mu2>1</mu2>
              </ode>
              <torsional>
                <ode/>
              </torsional>
            </friction>
            <bounce/>
          </surface>
          <max_contacts>10</max_contacts>
        </collision>
        <visual name='visual'>
          <pose>0.1 0 0 0 1.57079 0</pose>
          <geometry>
            <cylinder>
              <length>0.2</length>
              <radius>0.025</radius>
            </cylinder>
          </geometry>
          <material>
            <script>
              <uri>model://fire_hose_long_curled/materials/scripts</uri>
              <uri>model://fire_hose_long_curled/materials/textures</uri>
              <name>fire_hose_long_curled/fire_hose_canvas</name>
            </script>
          </material>
        </visual>
        <visual name='sphere'>
          <geometry>
            <sphere>
              <radius>0.025</radius>
            </sphere>
          </geometry>
          <material>
            <script>
              <uri>model://fire_hose_long_curled/materials/scripts</uri>
              <uri>model://fire_hose_long_curled/materials/textures</uri>
              <name>fire_hose_long_curled/fire_hose_canvas</name>
            </script>
          </material>
        </visual>
        <self_collide>0</self_collide>
        <enable_wind>0</enable_wind>
        <kinematic>0</kinematic>
      </link>
      <link name='nozzle'>
        <pose>1.1 -0.508 0 0 -0 3.1415</pose>
        <inertial>
          <mass>0.1</mass>
          <inertia>
            <ixx>0.01</ixx>
            <ixy>0</ixy>
            <ixz>0</ixz>
            <iyy>0.01</iyy>
            <iyz>0</iyz>
            <izz>0.01</izz>
          </inertia>
          <pose>0 0 0 0 -0 0</pose>
        </inertial>
        <collision name='nozzle_collision'>
          <geometry>
            <mesh>
              <scale>1 0.5 0.5</scale>
              <uri>model://fire_hose_long_curled/meshes/nozzle.stl</uri>
            </mesh>
          </geometry>
          <surface>
            <contact>
              <ode>
                <min_depth>0.005</min_depth>
              </ode>
            </contact>
            <friction>
              <ode>
                <mu>1</mu>
                <mu2>1</mu2>
              </ode>
              <torsional>
                <ode/>
              </torsional>
            </friction>
            <bounce/>
          </surface>
          <max_contacts>10</max_contacts>
        </collision>
        <visual name='nozzle_vis'>
          <geometry>
            <mesh>
              <scale>1 0.5 0.5</scale>
              <uri>model://fire_hose_long_curled/meshes/nozzle.stl</uri>
            </mesh>
          </geometry>
        </visual>
        <self_collide>0</self_collide>
        <enable_wind>0</enable_wind>
        <kinematic>0</kinematic>
      </link>
      <joint name='joint_00' type='revolute'>
        <parent>coupling</parent>
        <child>link_00</child>
        <axis>
          <xyz expressed_in='__model__'>1 0 0</xyz>
          <dynamics>
            <damping>1</damping>
            <spring_reference>0</spring_reference>
            <spring_stiffness>0</spring_stiffness>
          </dynamics>
          <limit>
            <lower>-1e+16</lower>
            <upper>1e+16</upper>
          </limit>
        </axis>
        <physics>
          <ode>
            <cfm_damping>1</cfm_damping>
            <limit>
              <cfm>0</cfm>
              <erp>0.2</erp>
            </limit>
          </ode>
        </physics>
      </joint>
      <joint name='joint_01' type='universal'>
        <child>link_01</child>
        <parent>link_00</parent>
        <axis>
          <xyz expressed_in='__model__'>0 1 0</xyz>
          <limit>
            <lower>-1.57</lower>
            <upper>1.57</upper>
          </limit>
          <dynamics>
            <damping>1</damping>
            <spring_reference>0</spring_reference>
            <spring_stiffness>0</spring_stiffness>
          </dynamics>
        </axis>
        <axis2>
          <xyz expressed_in='__model__'>0 0 1</xyz>
          <limit>
            <lower>-1.57</lower>
            <upper>1.57</upper>
          </limit>
          <dynamics>
            <damping>1</damping>
            <spring_reference>0</spring_reference>
            <spring_stiffness>0</spring_stiffness>
          </dynamics>
        </axis2>
        <physics>
          <ode>
            <cfm_damping>1</cfm_damping>
            <limit>
              <cfm>0</cfm>
              <erp>0.2</erp>
            </limit>
          </ode>
        </physics>
      </joint>
      <joint name='joint_02' type='universal'>
        <child>link_02</child>
        <parent>link_01</parent>
        <axis>
          <xyz expressed_in='__model__'>0 1 0</xyz>
          <limit>
            <lower>-1.57</lower>
            <upper>1.57</upper>
          </limit>
          <dynamics>
            <damping>1</damping>
            <spring_reference>0</spring_reference>
            <spring_stiffness>0</spring_stiffness>
          </dynamics>
        </axis>
        <axis2>
          <xyz expressed_in='__model__'>0 0 1</xyz>
          <limit>
            <lower>-1.57</lower>
            <upper>1.57</upper>
          </limit>
          <dynamics>
            <damping>1</damping>
            <spring_reference>0</spring_reference>
            <spring_stiffness>0</spring_stiffness>
          </dynamics>
        </axis2>
        <physics>
          <ode>
            <cfm_damping>1</cfm_damping>
            <limit>
              <cfm>0</cfm>
              <erp>0.2</erp>
            </limit>
          </ode>
        </physics>
      </joint>
      <joint name='joint_03' type='universal'>
        <child>link_03</child>
        <parent>link_02</parent>
        <axis>
          <xyz expressed_in='__model__'>0 1 0</xyz>
          <limit>
            <lower>-1.57</lower>
            <upper>1.57</upper>
          </limit>
          <dynamics>
            <damping>1</damping>
            <spring_reference>0</spring_reference>
            <spring_stiffness>0</spring_stiffness>
          </dynamics>
        </axis>
        <axis2>
          <xyz expressed_in='__model__'>0 0 1</xyz>
          <limit>
            <lower>-1.57</lower>
            <upper>1.57</upper>
          </limit>
          <dynamics>
            <damping>1</damping>
            <spring_reference>0</spring_reference>
            <spring_stiffness>0</spring_stiffness>
          </dynamics>
        </axis2>
        <physics>
          <ode>
            <cfm_damping>1</cfm_damping>
            <limit>
              <cfm>0</cfm>
              <erp>0.2</erp>
            </limit>
          </ode>
        </physics>
      </joint>
      <joint name='joint_04' type='universal'>
        <child>link_04</child>
        <parent>link_03</parent>
        <axis>
          <xyz expressed_in='__model__'>0 1 0</xyz>
          <limit>
            <lower>-1.57</lower>
            <upper>1.57</upper>
          </limit>
          <dynamics>
            <damping>1</damping>
            <spring_reference>0</spring_reference>
            <spring_stiffness>0</spring_stiffness>
          </dynamics>
        </axis>
        <axis2>
          <xyz expressed_in='__model__'>0 0 1</xyz>
          <limit>
            <lower>-1.57</lower>
            <upper>1.57</upper>
          </limit>
          <dynamics>
            <damping>1</damping>
            <spring_reference>0</spring_reference>
            <spring_stiffness>0</spring_stiffness>
          </dynamics>
        </axis2>
        <physics>
          <ode>
            <cfm_damping>1</cfm_damping>
            <limit>
              <cfm>0</cfm>
              <erp>0.2</erp>
            </limit>
          </ode>
        </physics>
      </joint>
      <joint name='joint_05' type='universal'>
        <child>link_05</child>
        <parent>link_04</parent>
        <axis>
          <xyz expressed_in='__model__'>0 1 0</xyz>
          <limit>
            <lower>-1.57</lower>
            <upper>1.57</upper>
          </limit>
          <dynamics>
            <damping>1</damping>
            <spring_reference>0</spring_reference>
            <spring_stiffness>0</spring_stiffness>
          </dynamics>
        </axis>
        <axis2>
          <xyz expressed_in='__model__'>0 0 1</xyz>
          <limit>
            <lower>-1.57</lower>
            <upper>1.57</upper>
          </limit>
          <dynamics>
            <damping>1</damping>
            <spring_reference>0</spring_reference>
            <spring_stiffness>0</spring_stiffness>
          </dynamics>
        </axis2>
        <physics>
          <ode>
            <cfm_damping>1</cfm_damping>
            <limit>
              <cfm>0</cfm>
              <erp>0.2</erp>
            </limit>
          </ode>
        </physics>
      </joint>
      <joint name='joint_06' type='universal'>
        <child>link_06</child>
        <parent>link_05</parent>
        <axis>
          <xyz expressed_in='__model__'>0 0 1</xyz>
          <limit>
            <lower>-0.72</lower>
            <upper>2.35</upper>
          </limit>
          <dynamics>
            <damping>1</damping>
            <spring_reference>0</spring_reference>
            <spring_stiffness>0</spring_stiffness>
          </dynamics>
        </axis>
        <axis2>
          <xyz expressed_in='__model__'>1 1 0</xyz>
          <limit>
            <lower>-1.57</lower>
            <upper>1.57</upper>
          </limit>
          <dynamics>
            <damping>1</damping>
            <spring_reference>0</spring_reference>
            <spring_stiffness>0</spring_stiffness>
          </dynamics>
        </axis2>
        <physics>
          <ode>
            <cfm_damping>1</cfm_damping>
            <limit>
              <cfm>0</cfm>
              <erp>0.2</erp>
            </limit>
          </ode>
        </physics>
      </joint>
      <joint name='joint_07' type='universal'>
        <child>link_07</child>
        <parent>link_06</parent>
        <axis>
          <xyz expressed_in='__model__'>0 0 1</xyz>
          <limit>
            <lower>-0</lower>
            <upper>3</upper>
          </limit>
          <dynamics>
            <damping>1</damping>
            <spring_reference>0</spring_reference>
            <spring_stiffness>0</spring_stiffness>
          </dynamics>
        </axis>
        <axis2>
          <xyz expressed_in='__model__'>-1 1 0</xyz>
          <limit>
            <lower>-1.57</lower>
            <upper>1.57</upper>
          </limit>
          <dynamics>
            <damping>1</damping>
            <spring_reference>0</spring_reference>
            <spring_stiffness>0</spring_stiffness>
          </dynamics>
        </axis2>
        <physics>
          <ode>
            <cfm_damping>1</cfm_damping>
            <limit>
              <cfm>0</cfm>
              <erp>0.2</erp>
            </limit>
          </ode>
        </physics>
      </joint>
      <joint name='joint_08' type='universal'>
        <child>link_08</child>
        <parent>link_07</parent>
        <axis>
          <xyz expressed_in='__model__'>0 1 0</xyz>
          <limit>
            <lower>-1.57</lower>
            <upper>1.57</upper>
          </limit>
          <dynamics>
            <damping>1</damping>
            <spring_reference>0</spring_reference>
            <spring_stiffness>0</spring_stiffness>
          </dynamics>
        </axis>
        <axis2>
          <xyz expressed_in='__model__'>0 0 1</xyz>
          <limit>
            <lower>-0.72</lower>
            <upper>2.35</upper>
          </limit>
          <dynamics>
            <damping>1</damping>
            <spring_reference>0</spring_reference>
            <spring_stiffness>0</spring_stiffness>
          </dynamics>
        </axis2>
        <physics>
          <ode>
            <cfm_damping>1</cfm_damping>
            <limit>
              <cfm>0</cfm>
              <erp>0.2</erp>
            </limit>
          </ode>
        </physics>
      </joint>
      <joint name='joint_09' type='universal'>
        <child>link_09</child>
        <parent>link_08</parent>
        <axis>
          <xyz expressed_in='__model__'>0 1 0</xyz>
          <limit>
            <lower>-1.57</lower>
            <upper>1.57</upper>
          </limit>
          <dynamics>
            <damping>1</damping>
            <spring_reference>0</spring_reference>
            <spring_stiffness>0</spring_stiffness>
          </dynamics>
        </axis>
        <axis2>
          <xyz expressed_in='__model__'>0 0 1</xyz>
          <limit>
            <lower>-1.57</lower>
            <upper>1.57</upper>
          </limit>
          <dynamics>
            <damping>1</damping>
            <spring_reference>0</spring_reference>
            <spring_stiffness>0</spring_stiffness>
          </dynamics>
        </axis2>
        <physics>
          <ode>
            <cfm_damping>1</cfm_damping>
            <limit>
              <cfm>0</cfm>
              <erp>0.2</erp>
            </limit>
          </ode>
        </physics>
      </joint>
      <joint name='joint_10' type='universal'>
        <child>link_10</child>
        <parent>link_09</parent>
        <axis>
          <xyz expressed_in='__model__'>0 1 0</xyz>
          <limit>
            <lower>-1.57</lower>
            <upper>1.57</upper>
          </limit>
          <dynamics>
            <damping>1</damping>
            <spring_reference>0</spring_reference>
            <spring_stiffness>0</spring_stiffness>
          </dynamics>
        </axis>
        <axis2>
          <xyz expressed_in='__model__'>0 0 1</xyz>
          <limit>
            <lower>-1.57</lower>
            <upper>1.57</upper>
          </limit>
          <dynamics>
            <damping>1</damping>
            <spring_reference>0</spring_reference>
            <spring_stiffness>0</spring_stiffness>
          </dynamics>
        </axis2>
        <physics>
          <ode>
            <cfm_damping>1</cfm_damping>
            <limit>
              <cfm>0</cfm>
              <erp>0.2</erp>
            </limit>
          </ode>
        </physics>
      </joint>
      <joint name='joint_11' type='universal'>
        <child>link_11</child>
        <parent>link_10</parent>
        <axis>
          <xyz expressed_in='__model__'>0 1 0</xyz>
          <limit>
            <lower>-1.57</lower>
            <upper>1.57</upper>
          </limit>
          <dynamics>
            <damping>1</damping>
            <spring_reference>0</spring_reference>
            <spring_stiffness>0</spring_stiffness>
          </dynamics>
        </axis>
        <axis2>
          <xyz expressed_in='__model__'>0 0 1</xyz>
          <limit>
            <lower>-1.57</lower>
            <upper>1.57</upper>
          </limit>
          <dynamics>
            <damping>1</damping>
            <spring_reference>0</spring_reference>
            <spring_stiffness>0</spring_stiffness>
          </dynamics>
        </axis2>
        <physics>
          <ode>
            <cfm_damping>1</cfm_damping>
            <limit>
              <cfm>0</cfm>
              <erp>0.2</erp>
            </limit>
          </ode>
        </physics>
      </joint>
      <joint name='joint_12' type='universal'>
        <child>link_12</child>
        <parent>link_11</parent>
        <axis>
          <xyz expressed_in='__model__'>0 1 0</xyz>
          <limit>
            <lower>-1.57</lower>
            <upper>1.57</upper>
          </limit>
          <dynamics>
            <damping>1</damping>
            <spring_reference>0</spring_reference>
            <spring_stiffness>0</spring_stiffness>
          </dynamics>
        </axis>
        <axis2>
          <xyz expressed_in='__model__'>0 0 1</xyz>
          <limit>
            <lower>-1.57</lower>
            <upper>1.57</upper>
          </limit>
          <dynamics>
            <damping>1</damping>
            <spring_reference>0</spring_reference>
            <spring_stiffness>0</spring_stiffness>
          </dynamics>
        </axis2>
        <physics>
          <ode>
            <cfm_damping>1</cfm_damping>
            <limit>
              <cfm>0</cfm>
              <erp>0.2</erp>
            </limit>
          </ode>
        </physics>
      </joint>
      <joint name='joint_13' type='universal'>
        <child>link_13</child>
        <parent>link_12</parent>
        <axis>
          <xyz expressed_in='__model__'>0 0 1</xyz>
          <limit>
            <lower>-2.35</lower>
            <upper>0.72</upper>
          </limit>
          <dynamics>
            <damping>1</damping>
            <spring_reference>0</spring_reference>
            <spring_stiffness>0</spring_stiffness>
          </dynamics>
        </axis>
        <axis2>
          <xyz expressed_in='__model__'>-1 1 0</xyz>
          <limit>
            <lower>-1.57</lower>
            <upper>1.57</upper>
          </limit>
          <dynamics>
            <damping>1</damping>
            <spring_reference>0</spring_reference>
            <spring_stiffness>0</spring_stiffness>
          </dynamics>
        </axis2>
        <physics>
          <ode>
            <cfm_damping>1</cfm_damping>
            <limit>
              <cfm>0</cfm>
              <erp>0.2</erp>
            </limit>
          </ode>
        </physics>
      </joint>
      <joint name='joint_14' type='universal'>
        <child>link_14</child>
        <parent>link_13</parent>
        <axis>
          <xyz expressed_in='__model__'>0 0 1</xyz>
          <limit>
            <lower>-3</lower>
            <upper>0</upper>
          </limit>
          <dynamics>
            <damping>1</damping>
            <spring_reference>0</spring_reference>
            <spring_stiffness>0</spring_stiffness>
          </dynamics>
        </axis>
        <axis2>
          <xyz expressed_in='__model__'>1 1 0</xyz>
          <limit>
            <lower>-1.57</lower>
            <upper>1.57</upper>
          </limit>
          <dynamics>
            <damping>1</damping>
            <spring_reference>0</spring_reference>
            <spring_stiffness>0</spring_stiffness>
          </dynamics>
        </axis2>
        <physics>
          <ode>
            <cfm_damping>1</cfm_damping>
            <limit>
              <cfm>0</cfm>
              <erp>0.2</erp>
            </limit>
          </ode>
        </physics>
      </joint>
      <joint name='joint_15' type='universal'>
        <child>link_15</child>
        <parent>link_14</parent>
        <axis>
          <xyz expressed_in='__model__'>0 0 1</xyz>
          <limit>
            <lower>-2.35</lower>
            <upper>0.72</upper>
          </limit>
          <dynamics>
            <damping>1</damping>
            <spring_reference>0</spring_reference>
            <spring_stiffness>0</spring_stiffness>
          </dynamics>
        </axis>
        <axis2>
          <xyz expressed_in='__model__'>0 1 0</xyz>
          <limit>
            <lower>-1.57</lower>
            <upper>1.57</upper>
          </limit>
          <dynamics>
            <damping>1</damping>
            <spring_reference>0</spring_reference>
            <spring_stiffness>0</spring_stiffness>
          </dynamics>
        </axis2>
        <physics>
          <ode>
            <cfm_damping>1</cfm_damping>
            <limit>
              <cfm>0</cfm>
              <erp>0.2</erp>
            </limit>
          </ode>
        </physics>
      </joint>
      <joint name='joint_16' type='universal'>
        <child>link_16</child>
        <parent>link_15</parent>
        <axis>
          <xyz expressed_in='__model__'>0 1 0</xyz>
          <limit>
            <lower>-1.57</lower>
            <upper>1.57</upper>
          </limit>
          <dynamics>
            <damping>1</damping>
            <spring_reference>0</spring_reference>
            <spring_stiffness>0</spring_stiffness>
          </dynamics>
        </axis>
        <axis2>
          <xyz expressed_in='__model__'>0 0 1</xyz>
          <limit>
            <lower>-1.57</lower>
            <upper>1.57</upper>
          </limit>
          <dynamics>
            <damping>1</damping>
            <spring_reference>0</spring_reference>
            <spring_stiffness>0</spring_stiffness>
          </dynamics>
        </axis2>
        <physics>
          <ode>
            <cfm_damping>1</cfm_damping>
            <limit>
              <cfm>0</cfm>
              <erp>0.2</erp>
            </limit>
          </ode>
        </physics>
      </joint>
      <joint name='joint_17' type='universal'>
        <child>link_17</child>
        <parent>link_16</parent>
        <axis>
          <xyz expressed_in='__model__'>0 1 0</xyz>
          <limit>
            <lower>-1.57</lower>
            <upper>1.57</upper>
          </limit>
          <dynamics>
            <damping>1</damping>
            <spring_reference>0</spring_reference>
            <spring_stiffness>0</spring_stiffness>
          </dynamics>
        </axis>
        <axis2>
          <xyz expressed_in='__model__'>0 0 1</xyz>
          <limit>
            <lower>-1.57</lower>
            <upper>1.57</upper>
          </limit>
          <dynamics>
            <damping>1</damping>
            <spring_reference>0</spring_reference>
            <spring_stiffness>0</spring_stiffness>
          </dynamics>
        </axis2>
        <physics>
          <ode>
            <cfm_damping>1</cfm_damping>
            <limit>
              <cfm>0</cfm>
              <erp>0.2</erp>
            </limit>
          </ode>
        </physics>
      </joint>
      <joint name='joint_18' type='universal'>
        <child>link_18</child>
        <parent>link_17</parent>
        <axis>
          <xyz expressed_in='__model__'>0 1 0</xyz>
          <limit>
            <lower>-1.57</lower>
            <upper>1.57</upper>
          </limit>
          <dynamics>
            <damping>1</damping>
            <spring_reference>0</spring_reference>
            <spring_stiffness>0</spring_stiffness>
          </dynamics>
        </axis>
        <axis2>
          <xyz expressed_in='__model__'>0 0 1</xyz>
          <limit>
            <lower>-1.57</lower>
            <upper>1.57</upper>
          </limit>
          <dynamics>
            <damping>1</damping>
            <spring_reference>0</spring_reference>
            <spring_stiffness>0</spring_stiffness>
          </dynamics>
        </axis2>
        <physics>
          <ode>
            <cfm_damping>1</cfm_damping>
            <limit>
              <cfm>0</cfm>
              <erp>0.2</erp>
            </limit>
          </ode>
        </physics>
      </joint>
      <joint name='joint_19' type='universal'>
        <child>link_19</child>
        <parent>link_18</parent>
        <axis>
          <xyz expressed_in='__model__'>0 1 0</xyz>
          <limit>
            <lower>-1.57</lower>
            <upper>1.57</upper>
          </limit>
          <dynamics>
            <damping>1</damping>
            <spring_reference>0</spring_reference>
            <spring_stiffness>0</spring_stiffness>
          </dynamics>
        </axis>
        <axis2>
          <xyz expressed_in='__model__'>0 0 1</xyz>
          <limit>
            <lower>-1.57</lower>
            <upper>1.57</upper>
          </limit>
          <dynamics>
            <damping>1</damping>
            <spring_reference>0</spring_reference>
            <spring_stiffness>0</spring_stiffness>
          </dynamics>
        </axis2>
        <physics>
          <ode>
            <cfm_damping>1</cfm_damping>
            <limit>
              <cfm>0</cfm>
              <erp>0.2</erp>
            </limit>
          </ode>
        </physics>
      </joint>
      <joint name='joint_20' type='universal'>
        <child>nozzle</child>
        <parent>link_19</parent>
        <axis>
          <xyz expressed_in='__model__'>0 1 0</xyz>
          <limit>
            <lower>-1.57</lower>
            <upper>1.57</upper>
          </limit>
          <dynamics>
            <damping>1</damping>
            <spring_reference>0</spring_reference>
            <spring_stiffness>0</spring_stiffness>
          </dynamics>
        </axis>
        <axis2>
          <xyz expressed_in='__model__'>0 0 1</xyz>
          <limit>
            <lower>-1.57</lower>
            <upper>1.57</upper>
          </limit>
          <dynamics>
            <damping>1</damping>
            <spring_reference>0</spring_reference>
            <spring_stiffness>0</spring_stiffness>
          </dynamics>
        </axis2>
        <physics>
          <ode>
            <cfm_damping>1</cfm_damping>
            <limit>
              <cfm>0</cfm>
              <erp>0.2</erp>
            </limit>
          </ode>
        </physics>
      </joint>
      <joint name='world' type='universal'>
        <child>nozzle</child>
        <parent>world</parent>
        <axis>
          <xyz expressed_in='__model__'>0 1 0</xyz>
          <limit>
            <lower>-1.57</lower>
            <upper>1.57</upper>
          </limit>
          <dynamics>
            <damping>1</damping>
            <spring_reference>0</spring_reference>
            <spring_stiffness>0</spring_stiffness>
          </dynamics>
        </axis>
        <axis2>
          <xyz expressed_in='__model__'>0 0 1</xyz>
          <limit>
            <lower>-1.57</lower>
            <upper>1.57</upper>
          </limit>
          <dynamics>
            <damping>1</damping>
            <spring_reference>0</spring_reference>
            <spring_stiffness>0</spring_stiffness>
          </dynamics>
        </axis2>
        <physics>
          <ode>
            <cfm_damping>1</cfm_damping>
            <limit>
              <cfm>0</cfm>
              <erp>0.2</erp>
            </limit>
          </ode>
        </physics>
      </joint>
    </model>
    <model name='fire_hydrant'>
      <static>1</static>
      <link name='link'>
        <collision name='collision'>
          <geometry>
            <mesh>
              <uri>model://fire_hydrant/meshes/fire_hydrant.dae</uri>
            </mesh>
          </geometry>
          <max_contacts>10</max_contacts>
          <surface>
            <contact>
              <ode/>
            </contact>
            <bounce/>
            <friction>
              <torsional>
                <ode/>
              </torsional>
              <ode/>
            </friction>
          </surface>
        </collision>
        <visual name='visual'>
          <geometry>
            <mesh>
              <uri>model://fire_hydrant/meshes/fire_hydrant.dae</uri>
            </mesh>
          </geometry>
        </visual>
        <self_collide>0</self_collide>
        <enable_wind>0</enable_wind>
        <kinematic>0</kinematic>
      </link>
      <pose>3.81568 -1.06197 0 0 -0 0</pose>
    </model>
    <model name='postbox'>
      <static>1</static>
      <link name='link'>
        <collision name='collision'>
          <geometry>
            <mesh>
              <uri>model://postbox/meshes/postbox.dae</uri>
            </mesh>
          </geometry>
          <max_contacts>10</max_contacts>
          <surface>
            <contact>
              <ode/>
            </contact>
            <bounce/>
            <friction>
              <torsional>
                <ode/>
              </torsional>
              <ode/>
            </friction>
          </surface>
        </collision>
        <visual name='visual'>
          <geometry>
            <mesh>
              <uri>model://postbox/meshes/postbox.dae</uri>
            </mesh>
          </geometry>
        </visual>
        <self_collide>0</self_collide>
        <enable_wind>0</enable_wind>
        <kinematic>0</kinematic>
      </link>
      <pose>-0.488927 1.66345 0 0 -0 0</pose>
    </model>
    <state world_name='default'>
      <sim_time>356 607000000</sim_time>
      <real_time>359 908668894</real_time>
      <wall_time>1767853905 668059651</wall_time>
      <iterations>356607</iterations>
      <model name='Mailbox'>
        <pose>1.06504 -1.05431 -9e-06 4e-06 -8e-06 0</pose>
        <scale>1 1 1</scale>
        <link name='link'>
          <pose>1.06504 -1.05431 -9e-06 4e-06 -8e-06 0</pose>
          <velocity>0 0 0 0 -0 0</velocity>
          <acceleration>0 0 -9.8 0 -0 0</acceleration>
          <wrench>0 0 -9.8 0 -0 0</wrench>
        </link>
      </model>
      <model name='bookshelf'>
        <pose>-2.58056 -2.00343 0 0 -0 1.5766</pose>
        <scale>1 1 1</scale>
        <link name='link'>
          <pose>-2.58056 -2.00343 0 0 -0 1.5766</pose>
          <velocity>0 0 0 0 -0 0</velocity>
          <acceleration>0 0 0 0 -0 0</acceleration>
          <wrench>0 0 0 0 -0 0</wrench>
        </link>
      </model>
      <model name='cafe_table'>
        <pose>-1.50845 1.52359 0 0 -0 0</pose>
        <scale>1 1 1</scale>
        <link name='link'>
          <pose>-1.50845 1.52359 0 0 -0 0</pose>
          <velocity>0 0 0 0 -0 0</velocity>
          <acceleration>0 0 0 0 -0 0</acceleration>
          <wrench>0 0 0 0 -0 0</wrench>
        </link>
      </model>
      <model name='cafe_table_0'>
        <pose>1.05085 1.48026 0 0 -0 0</pose>
        <scale>1 1 1</scale>
        <link name='link'>
          <pose>1.05085 1.48026 0 0 -0 0</pose>
          <velocity>0 0 0 0 -0 0</velocity>
          <acceleration>0 0 0 0 -0 0</acceleration>
          <wrench>0 0 0 0 -0 0</wrench>
        </link>
      </model>
      <model name='cinder_block_wide'>
        <pose>-2.42354 -2.88384 -0.000251 0 -0 0</pose>
        <scale>1 1 1</scale>
        <link name='link'>
          <pose>-2.42354 -2.88384 -0.000251 0 -0 0</pose>
          <velocity>0 0 0 0 -0 0</velocity>
          <acceleration>0 -0 -0 0 -0 0</acceleration>
          <wrench>0 -0 -0 0 -0 0</wrench>
        </link>
      </model>
      <model name='fire_hose_long_curled'>
        <pose>2.50916 -0.590942 0.043394 -2.6e-05 0.103029 0.000973</pose>
        <scale>1 1 1</scale>
        <link name='coupling'>
          <pose>2.50916 -0.590942 0.043394 -2.6e-05 0.103029 0.000973</pose>
          <velocity>1.6e-05 -0.000132 -4.2e-05 0.003033 0.00036 4.7e-05</velocity>
          <acceleration>0.026296 -0.216755 -0.024705 -2.07514 0.505015 0.052925</acceleration>
          <wrench>0.00263 -0.021675 -0.002471 0 -0 0</wrench>
        </link>
        <link name='link_00'>
          <pose>2.60863 -0.590845 0.03311 0.006472 0.103029 0.000974</pose>
          <velocity>-1.4e-05 -9.9e-05 -6.8e-05 -0.000384 0.000349 0.000441</velocity>
          <acceleration>-0.0154 -0.078152 -0.144165 -0.543881 0.484186 0.610759</acceleration>
          <wrench>-0.00154 -0.007815 -0.014417 0 -0 0</wrench>
        </link>
        <link name='link_01'>
          <pose>2.60863 -0.590845 0.03311 0.006384 0.040668 -0.000872</pose>
          <velocity>-1.5e-05 -8.8e-05 -6.1e-05 -0.000379 -0.000443 0.000504</velocity>
          <acceleration>-0.016748 -0.053548 -0.064823 -0.537252 -0.573563 0.696998</acceleration>
          <wrench>-0.001675 -0.005355 -0.006482 0 -0 0</wrench>
        </link>
        <link name='link_02'>
          <pose>2.80846 -0.591019 0.024978 0.006379 -0.000109 0.000352</pose>
          <velocity>-2e-06 -7e-06 0.000165 -0.000381 -0.000475 0.000118</velocity>
          <acceleration>0.021267 0.008618 0.152352 -0.538017 0.473832 0.11263</acceleration>
          <wrench>0.002127 0.000862 0.015235 0 -0 0</wrench>
        </link>
        <link name='link_03'>
          <pose>3.00846 -0.590949 0.025 0.006379 6e-06 -0.000263</pose>
          <velocity>1.2e-05 6e-06 0.000151 -0.000385 0.000481 4.6e-05</velocity>
          <acceleration>-0.020034 0.013916 0.239168 -0.541439 -0.868393 0.041628</acceleration>
          <wrench>-0.002003 0.001392 0.023917 0 -0 0</wrench>
        </link>
        <link name='link_04'>
          <pose>3.20846 -0.591001 0.024998 0.006379 -3e-06 -0.001055</pose>
          <velocity>-0.000218 1e-05 -4.5e-05 -0.000382 0.006628 2.1e-05</velocity>
          <acceleration>-0.203016 0.0142 -0.768996 -0.538235 0.964021 0.006716</acceleration>
          <wrench>-0.020302 0.00142 -0.0769 0 -0 0</wrench>
        </link>
        <link name='link_05'>
          <pose>3.40846 -0.591212 0.024999 0.006379 -0 0.000291</pose>
          <velocity>-0.000173 -2e-06 -0.00132 -0.000394 -0.00686 6.4e-05</velocity>
          <acceleration>-0.185415 0.007501 -0.728833 -0.550523 -1.0934 0.038042</acceleration>
          <wrench>-0.018542 0.00075 -0.072883 0 -0 0</wrench>
        </link>
        <link name='link_06'>
          <pose>3.60846 -0.591154 0.024998 0.004485 -1.2e-05 -0.790193</pose>
          <velocity>-3.1e-05 0.000215 -1e-06 0.002742 -0.003768 5.1e-05</velocity>
          <acceleration>-0.015533 0.208742 0.053594 0.232111 0.381776 -2.99252</acceleration>
          <wrench>-0.001553 0.020874 0.005359 0 -0 0</wrench>
        </link>
        <link name='link_07'>
          <pose>3.7348 -0.718812 0.025001 1.3e-05 7e-06 -2.34623</pose>
          <velocity>-3.8e-05 1.3e-05 0.000171 -4.3e-05 -0.001044 0.000238</velocity>
          <acceleration>-0.000942 -0.000502 0.008518 -0.080166 -0.139289 0.219974</acceleration>
          <wrench>-9.4e-05 -5e-05 0.000852 0 -0 0</wrench>
        </link>
        <link name='link_08'>
          <pose>3.6072 -0.84521 0.024998 3e-06 -7e-06 3.14127</pose>
          <velocity>2.4e-05 -0 -4.2e-05 2.1e-05 0.001013 -2e-06</velocity>
          <acceleration>0.055976 0.003484 -0.022809 -0.071947 -0.227276 -0.012326</acceleration>
          <wrench>0.005598 0.000348 -0.002281 0 -0 0</wrench>
        </link>
        <link name='link_09'>
          <pose>3.4072 -0.845126 0.025 3e-06 5e-06 -3.14148</pose>
          <velocity>-2.7e-05 -1e-06 -1e-06 2.4e-05 -0.001127 -1e-06</velocity>
          <acceleration>-0.016708 0.002317 -0.193618 -0.087591 -0.714085 -0.001745</acceleration>
          <wrench>-0.001671 0.000232 -0.019362 0 -0 0</wrench>
        </link>
        <link name='link_10'>
          <pose>3.2072 -0.84513 0.024998 3e-06 -4e-06 3.14113</pose>
          <velocity>8e-06 -1e-06 -9e-05 1.6e-05 0.000324 -2e-06</velocity>
          <acceleration>0.016188 0.00452 -0.338589 -0.101255 0.132241 0.007783</acceleration>
          <wrench>0.001619 0.000452 -0.033859 0 -0 0</wrench>
        </link>
        <link name='link_11'>
          <pose>3.0072 -0.84502 0.025 3e-06 2e-06 -3.14156</pose>
          <velocity>-1.9e-05 0 0.000198 8e-06 -0.000752 4e-06</velocity>
          <acceleration>-0.00886 0.002831 0.041102 -0.105494 -0.354556 -0.01086</acceleration>
          <wrench>-0.000886 0.000283 0.00411 0 -0 0</wrench>
        </link>
        <link name='link_12'>
          <pose>2.8072 -0.845007 0.024998 3e-06 -1.1e-05 3.13848</pose>
          <velocity>1.7e-05 -0 -4.7e-05 2e-06 0.000695 0.000114</velocity>
          <acceleration>0.029277 -0.032753 0.118474 -0.103101 1.18778 0.354011</acceleration>
          <wrench>0.002928 -0.003275 0.011847 0 -0 0</wrench>
        </link>
        <link name='link_13'>
          <pose>2.6072 -0.844365 0.025001 -6e-06 7e-06 -2.34559</pose>
          <velocity>3e-06 -2.3e-05 0.000141 0.000755 -5.1e-05 -7.5e-05</velocity>
          <acceleration>-0.015661 -0.045599 0.188184 1.80532 -0.638685 -0.095609</acceleration>
          <wrench>-0.001566 -0.00456 0.018818 0 -0 0</wrench>
        </link>
        <link name='link_14'>
          <pose>2.48153 -0.97268 0.024998 7e-06 -9e-06 -0.775995</pose>
          <velocity>-2.3e-05 1e-06 -3.9e-05 -5.7e-05 -0.000933 0.000113</velocity>
          <acceleration>-0.051316 -0.017938 -0.145629 -2.80632 -0.786233 -3.02533</acceleration>
          <wrench>-0.005132 -0.001794 -0.014563 0 -0 0</wrench>
        </link>
        <link name='link_15'>
          <pose>2.60967 -1.09853 0.025001 -1e-06 7e-06 -0.00323</pose>
          <velocity>1.5e-05 4e-06 0.000165 -4.7e-05 0.000595 -3.1e-05</velocity>
          <acceleration>0.001782 -0.008464 0.011628 0.352203 0.0713 0.019452</acceleration>
          <wrench>0.000178 -0.000846 0.001163 0 -0 0</wrench>
        </link>
        <link name='link_16'>
          <pose>2.80967 -1.09918 0.024998 -1e-06 -2e-06 0.002752</pose>
          <velocity>-1.1e-05 1e-06 -0.000134 -3.5e-05 -0.000538 1e-06</velocity>
          <acceleration>0.007072 0.00201 -0.115736 0.357054 0.229062 0.110332</acceleration>
          <wrench>0.000707 0.000201 -0.011574 0 -0 0</wrench>
        </link>
        <link name='link_17'>
          <pose>3.00967 -1.09863 0.024999 0 -0 0.016135</pose>
          <velocity>1.6e-05 2e-06 0.000171 -2.8e-05 0.000638 -1.4e-05</velocity>
          <acceleration>0.00495 -0.007784 0.023349 0.336891 0.19822 0.035618</acceleration>
          <wrench>0.000495 -0.000778 0.002335 0 -0 0</wrench>
        </link>
        <link name='link_18'>
          <pose>3.20964 -1.0954 0.024998 -1.4e-05 0.001431 0.006569</pose>
          <velocity>-1e-05 -2e-06 -9.4e-05 -5e-06 -0.000398 2.6e-05</velocity>
          <acceleration>-0.001055 -0.0099 -0.006051 0.31287 -0.042868 -0.117663</acceleration>
          <wrench>-0.000106 -0.00099 -0.000605 0 -0 0</wrench>
        </link>
        <link name='link_19'>
          <pose>3.40964 -1.09409 0.024712 0.004795 -0.152024 -0.025176</pose>
          <velocity>2e-06 0 1.8e-05 0 8.8e-05 5e-06</velocity>
          <acceleration>0.001154 0.00329 -0.001682 0.202758 0.022329 0.122831</acceleration>
          <wrench>0.000115 0.000329 -0.000168 0 -0 0</wrench>
        </link>
        <link name='nozzle'>
          <pose>3.60727 -1.09906 0.055 -0.0352 0.188307 2.95565</pose>
          <velocity>8e-06 -4e-06 1e-06 6e-06 0.000228 -7e-06</velocity>
          <acceleration>-0.001271 -0.000777 -0.002822 0.143466 0.149441 0.020031</acceleration>
          <wrench>-0.000127 -7.8e-05 -0.000282 0 -0 0</wrench>
        </link>
      </model>
      <model name='fire_hydrant'>
        <pose>3.81568 -1.06197 0 0 -0 0</pose>
        <scale>1 1 1</scale>
        <link name='link'>
          <pose>3.81568 -1.06197 0 0 -0 0</pose>
          <velocity>0 0 0 0 -0 0</velocity>
          <acceleration>0 0 0 0 -0 0</acceleration>
          <wrench>0 0 0 0 -0 0</wrench>
        </link>
      </model>
      <model name='first_2015_trash_can'>
        <pose>1.95328 -0.969355 -2e-06 6e-06 1e-05 -0.000638</pose>
        <scale>1 1 1</scale>
        <link name='link'>
          <pose>1.95328 -0.969355 -2e-06 6e-06 1e-05 -0.000638</pose>
          <velocity>0 0 0 0 -0 0</velocity>
          <acceleration>2.21708 0.074385 1.65573 -0.140808 -0.204444 0.026978</acceleration>
          <wrench>10.7102 0.359337 7.99843 0 -0 0</wrench>
        </link>
      </model>
      <model name='ground_plane'>
        <pose>0 0 0 0 -0 0</pose>
        <scale>1 1 1</scale>
        <link name='link'>
          <pose>0 0 0 0 -0 0</pose>
          <velocity>0 0 0 0 -0 0</velocity>
          <acceleration>0 0 0 0 -0 0</acceleration>
          <wrench>0 0 0 0 -0 0</wrench>
        </link>
      </model>
      <model name='postbox'>
        <pose>-0.300364 1.66345 0 0 -0 0</pose>
        <scale>1 1 1</scale>
        <link name='link'>
          <pose>-0.300364 1.66345 0 0 -0 0</pose>
          <velocity>0 0 0 0 -0 0</velocity>
          <acceleration>0 0 0 0 -0 0</acceleration>
          <wrench>0 0 0 0 -0 0</wrench>
        </link>
      </model>
      <model name='simple'>
        <pose>0.011754 -0.028761 0 0 -0 0</pose>
        <scale>1 1 1</scale>
        <link name='Wall_1'>
          <pose>0.386754 5.52124 0 0 -0 0</pose>
          <velocity>0 0 0 0 -0 0</velocity>
          <acceleration>0 0 0 0 -0 0</acceleration>
          <wrench>0 0 0 0 -0 0</wrench>
        </link>
        <link name='Wall_10'>
          <pose>3.68539 -1.44415 0 0 -0 3.14159</pose>
          <velocity>0 0 0 0 -0 0</velocity>
          <acceleration>0 0 0 0 -0 0</acceleration>
          <wrench>0 0 0 0 -0 0</wrench>
        </link>
        <link name='Wall_13'>
          <pose>-2.73946 -3.47606 0 0 -0 1.5708</pose>
          <velocity>0 0 0 0 -0 0</velocity>
          <acceleration>0 0 0 0 -0 0</acceleration>
          <wrench>0 0 0 0 -0 0</wrench>
        </link>
        <link name='Wall_2'>
          <pose>6.68675 -0.028761 0 0 0 -1.5708</pose>
          <velocity>0 0 0 0 -0 0</velocity>
          <acceleration>0 0 0 0 -0 0</acceleration>
          <wrench>0 0 0 0 -0 0</wrench>
        </link>
        <link name='Wall_3'>
          <pose>0.011754 -5.57876 0 0 -0 3.14159</pose>
          <velocity>0 0 0 0 -0 0</velocity>
          <acceleration>0 0 0 0 -0 0</acceleration>
          <wrench>0 0 0 0 -0 0</wrench>
        </link>
        <link name='Wall_4'>
          <pose>-6.66325 -0.028761 0 0 -0 1.5708</pose>
          <velocity>0 0 0 0 -0 0</velocity>
          <acceleration>0 0 0 0 -0 0</acceleration>
          <wrench>0 0 0 0 -0 0</wrench>
        </link>
        <link name='Wall_5'>
          <pose>0.011754 5.52124 0 0 -0 0</pose>
          <velocity>0 0 0 0 -0 0</velocity>
          <acceleration>0 0 0 0 -0 0</acceleration>
          <wrench>0 0 0 0 -0 0</wrench>
        </link>
        <link name='Wall_7'>
          <pose>-2.88788 3.84624 0 0 0 -1.5708</pose>
          <velocity>0 0 0 0 -0 0</velocity>
          <acceleration>0 0 0 0 -0 0</acceleration>
          <wrench>0 0 0 0 -0 0</wrench>
        </link>
        <link name='Wall_8'>
          <pose>-0.337872 2.17124 0 0 -0 0</pose>
          <velocity>0 0 0 0 -0 0</velocity>
          <acceleration>0 0 0 0 -0 0</acceleration>
          <wrench>0 0 0 0 -0 0</wrench>
        </link>
      </model>
      <model name='textured_shapes'>
        <pose>5.89701 1.17797 0.5 0 1e-06 0</pose>
        <scale>1 1 1</scale>
        <link name='box'>
          <pose>5.89701 -0.32203 0.5 0 1e-06 0</pose>
          <velocity>0 0 0 0 -0 0</velocity>
          <acceleration>-3.52797 -3.52798 7.8399 0.772739 -0.772735 0</acceleration>
          <wrench>-3.52797 -3.52798 7.8399 0 -0 0</wrench>
        </link>
        <link name='cylinder'>
          <pose>5.89701 2.67797 0.5 0 -0 0</pose>
          <velocity>0 0 0 0 -0 0</velocity>
          <acceleration>0 0 -9.8 0 -0 0</acceleration>
          <wrench>0 0 -9.8 0 -0 0</wrench>
        </link>
        <link name='sphere'>
          <pose>5.89701 1.17797 0.5 0 -0 0</pose>
          <velocity>0 0 0 0 -0 0</velocity>
          <acceleration>0 0 0 0 -0 0</acceleration>
          <wrench>0 0 0 0 -0 0</wrench>
        </link>
      </model>
      <light name='sun'>
        <pose>0 0 10 0 -0 0</pose>
      </light>
    </state>
    <gui fullscreen='0'>
      <camera name='user_camera'>
        <pose>1.20826 -16.1137 13.9667 -0 0.737795 1.31624</pose>
        <view_controller>orbit</view_controller>
        <projection_type>perspective</projection_type>
      </camera>
    </gui>
  </world>
</sdf>
